Workbook

Sheet %Accettato
A1: MESE | B1: POSITIVI | C1: NEGATIVI | D1: % Accettato | E1: % Non Accettato | G1: OPPORTUNITA' DI VENDITA | H1: POSITIVI | I1: NEGATIVI | J1: % Accettato | K1: % Non Accettato
A2: GENNAIO | B2: =COUNTIF(INDIRECT("'" & $A2 & "'!$A$11:$A$1000"), "INZIA IL TRATTAMENTO-VENDITA") -> 15 | C2: =COUNTIF(INDIRECT("'" & $A2 & "'!$A$11:$A$1000"), "NESSUNA VENDITA") -> 14 | D2: =IFERROR(B2 / (B2 + C2), 0) -> 0.51724138 | E2: =IFERROR(C2 / (B2 + C2), 0) -> 0.48275862 | G2: OPPORTUNITA' DI VENDITA | H2: {=COUNTIF(INDIRECT("'" & $G2 & "'!$B$198:$B$1000"), "ESEGUITO")} -> 5 | I2: {=COUNTIF(INDIRECT("'" & $G2 & "'!$B$198:$B$1000"), "NON ESEGUITO")} -> 0 | J2: =IFERROR(H2 / (H2 + I2), 0) -> 1 | K2: =IFERROR(I2 / (H2 + I2), 0) -> 0
A3: FEBBRAIO | B3: =COUNTIF(INDIRECT("'" & $A3 & "'!$A$11:$A$1000"), "INZIA IL TRATTAMENTO-VENDITA") -> 32 | C3: =COUNTIF(INDIRECT("'" & $A3 & "'!$A$11:$A$1000"), "NESSUNA VENDITA") -> 12 | D3: =IFERROR(B3 / (B3 + C3), 0) -> 0.72727273 | E3: =IFERROR(C3 / (B3 + C3), 0) -> 0.27272727
A4: MARZO | B4: =COUNTIF(INDIRECT("'" & $A4 & "'!$A$11:$A$1000"), "INZIA IL TRATTAMENTO-VENDITA") -> 29 | C4: =COUNTIF(INDIRECT("'" & $A4 & "'!$A$11:$A$1000"), "NESSUNA VENDITA") -> 21 | D4: =IFERROR(B4 / (B4 + C4), 0) -> 0.58 | E4: =IFERROR(C4 / (B4 + C4), 0) -> 0.42
A5: APRILE | B5: =COUNTIF(INDIRECT("'" & $A5 & "'!$A$11:$A$1000"), "INZIA IL TRATTAMENTO-VENDITA") -> 20 | C5: =COUNTIF(INDIRECT("'" & $A5 & "'!$A$11:$A$1000"), "NESSUNA VENDITA") -> 22 | D5: =IFERROR(B5 / (B5 + C5), 0) -> 0.47619048 | E5: =IFERROR(C5 / (B5 + C5), 0) -> 0.52380952
A6: MAGGIO | B6: =COUNTIF(INDIRECT("'" & $A6 & "'!$A$11:$A$1000"), "INZIA IL TRATTAMENTO-VENDITA") -> 31 | C6: =COUNTIF(INDIRECT("'" & $A6 & "'!$A$11:$A$1000"), "NESSUNA VENDITA") -> 7 | D6: =IFERROR(B6 / (B6 + C6), 0) -> 0.81578947 | E6: =IFERROR(C6 / (B6 + C6), 0) -> 0.18421053
A7: GIUGNO | B7: =COUNTIF(INDIRECT("'" & $A7 & "'!$A$11:$A$1000"), "INZIA IL TRATTAMENTO-VENDITA") -> 21 | C7: =COUNTIF(INDIRECT("'" & $A7 & "'!$A$11:$A$1000"), "NESSUNA VENDITA") -> 2 | D7: =IFERROR(B7 / (B7 + C7), 0) -> 0.91304348 | E7: =IFERROR(C7 / (B7 + C7), 0) -> 0.086956522
A8: LUGLIO | B8: =COUNTIF(INDIRECT("'" & $A8 & "'!$A$11:$A$1000"), "INZIA IL TRATTAMENTO-VENDITA") -> 0 | C8: =COUNTIF(INDIRECT("'" & $A8 & "'!$A$11:$A$1000"), "NESSUNA VENDITA") -> 0 | D8: =IFERROR(B8 / (B8 + C8), 0) -> 0 | E8: =IFERROR(C8 / (B8 + C8), 0) -> 0
A9: AGOSTO | B9: =COUNTIF(INDIRECT("'" & $A9 & "'!$A$11:$A$1000"), "INZIA IL TRATTAMENTO-VENDITA") -> 0 | C9: =COUNTIF(INDIRECT("'" & $A9 & "'!$A$11:$A$1000"), "NESSUNA VENDITA") -> 0 | D9: =IFERROR(B9 / (B9 + C9), 0) -> 0 | E9: =IFERROR(C9 / (B9 + C9), 0) -> 0
A10: SETTEMBRE | B10: =COUNTIF(INDIRECT("'" & $A10 & "'!$A$11:$A$1000"), "INZIA IL TRATTAMENTO-VENDITA") -> 0 | C10: =COUNTIF(INDIRECT("'" & $A10 & "'!$A$11:$A$1000"), "NESSUNA VENDITA") -> 0 | D10: =IFERROR(B10 / (B10 + C10), 0) -> 0 | E10: =IFERROR(C10 / (B10 + C10), 0) -> 0
A11: OTTOBRE | B11: =COUNTIF(INDIRECT("'" & $A11 & "'!$A$11:$A$1000"), "INZIA IL TRATTAMENTO-VENDITA") -> 0 | C11: =COUNTIF(INDIRECT("'" & $A11 & "'!$A$11:$A$1000"), "NESSUNA VENDITA") -> 0 | D11: =IFERROR(B11 / (B11 + C11), 0) -> 0 | E11: =IFERROR(C11 / (B11 + C11), 0) -> 0
A12: NOVEMBRE | B12: =COUNTIF(INDIRECT("'" & $A12 & "'!$A$11:$A$1000"), "INZIA IL TRATTAMENTO-VENDITA") -> 0 | C12: =COUNTIF(INDIRECT("'" & $A12 & "'!$A$11:$A$1000"), "NESSUNA VENDITA") -> 0 | D12: =IFERROR(B12 / (B12 + C12), 0) -> 0 | E12: =IFERROR(C12 / (B12 + C12), 0) -> 0
A13: DICEMBRE | B13: =COUNTIF(INDIRECT("'" & $A13 & "'!$A$11:$A$1000"), "INZIA IL TRATTAMENTO-VENDITA") -> 0 | C13: =COUNTIF(INDIRECT("'" & $A13 & "'!$A$11:$A$1000"), "NESSUNA VENDITA") -> 0 | D13: =IFERROR(B13 / (B13 + C13), 0) -> 0 | E13: =IFERROR(C13 / (B13 + C13), 0) -> 0

Sheet CONSUNTIVO
E1: nb. questo è un foglio dedicato al controllo, si prega di non modificare gli importi che sono generati automaticamente da formule incrociate.
B3: Consuntivo Annuale | C3: Opp.tà di Vendita | D3: Colonna 2 | E3: Preventivato Mese ACCETTATO | F3: 1 | G3: 2 | H3: 3 | I3: 4 | J3: 5 | K3: 6 | L3: 7 | M3: 8 | N3: 9 | O3: 10 | P3: 11 | Q3: 12 | R3: TOTALE | S3: ,,
F4: gennaio | G4: febbraio | H4: marzo | I4: aprile | J4: maggio | K4: giugno | L4: luglio | M4: agosto | N4: settembre | O4: ottobre | P4: novembre | Q4: dicembre
B5: DOMENICI | C5: =SUMIFS('OPPORTUNITA DI VENDITA'!$J$198:$J$1000, 'OPPORTUNITA DI VENDITA'!$H$198:$H$1000, B5, 'OPPORTUNITA DI VENDITA'!$B$198:$B$1000, "ESEGUITO") -> 0 | E5: DOMENICI | F5: =SUMIFS(INDIRECT("'" & $F$4 & "'!$I$11:$I$1000"), INDIRECT("'" & $F$4 & "'!$G$11:$G$1000"), $E5, INDIRECT("'" & $F$4 & "'!$A$11:$A$1000"), "INZIA IL TRATTAMENTO-VENDITA") -> 3285 | G5: =SUMIFS(INDIRECT("'" & $G$4 & "'!$I$11:$I$1000"), INDIRECT("'" & $G$4 & "'!$G$11:$G$1000"), $E5, INDIRECT("'" & $G$4 & "'!$A$11:$A$1000"), "INZIA IL TRATTAMENTO-VENDITA") -> 63368 | H5: =SUMIFS(INDIRECT("'" & $H$4 & "'!$I$11:$I$1000"), INDIRECT("'" & $H$4 & "'!$G$11:$G$1000"), $E5, INDIRECT("'" & $H$4 & "'!$A$11:$A$1000"), "INZIA IL TRATTAMENTO-VENDITA") -> 2155 | I5: =SUMIFS(INDIRECT("'" & I$4 & "'!$I$11:$I$1000"), INDIRECT("'" & I$4 & "'!$G$11:$G$1000"), $E5, INDIRECT("'" & I$4 & "'!$A$11:$A$1000"), "INZIA IL TRATTAMENTO-VENDITA") -> 520 | J5: =SUMIFS(INDIRECT("'" & J$4 & "'!$I$11:$I$1000"), INDIRECT("'" & J$4 & "'!$G$11:$G$1000"), $E5, INDIRECT("'" & J$4 & "'!$A$11:$A$1000"), "INZIA IL TRATTAMENTO-VENDITA") -> 5637 | K5: =SUMIFS(INDIRECT("'" & K$4 & "'!$I$11:$I$1000"), INDIRECT("'" & K$4 & "'!$G$11:$G$1000"), $E5, INDIRECT("'" & K$4 & "'!$A$11:$A$1000"), "INZIA IL TRATTAMENTO-VENDITA") -> 5970 | L5: =SUMIFS(INDIRECT("'" & L$4 & "'!$I$11:$I$1000"), INDIRECT("'" & L$4 & "'!$G$11:$G$1000"), $E5, INDIRECT("'" & L$4 & "'!$A$11:$A$1000"), "INZIA IL TRATTAMENTO-VENDITA") -> 0 | M5: =SUMIFS(INDIRECT("'" & M$4 & "'!$I$11:$I$1000"), INDIRECT("'" & M$4 & "'!$G$11:$G$1000"), $E5, INDIRECT("'" & M$4 & "'!$A$11:$A$1000"), "INZIA IL TRATTAMENTO-VENDITA") -> 0 | N5: =SUMIFS(INDIRECT("'" & N$4 & "'!$I$11:$I$1000"), INDIRECT("'" & N$4 & "'!$G$11:$G$1000"), $E5, INDIRECT("'" & N$4 & "'!$A$11:$A$1000"), "INZIA IL TRATTAMENTO-VENDITA") -> 0 | O5: =SUMIFS(INDIRECT("'" & O$4 & "'!$I$11:$I$1000"), INDIRECT("'" & O$4 & "'!$G$11:$G$1000"), $E5, INDIRECT("'" & O$4 & "'!$A$11:$A$1000"), "INZIA IL TRATTAMENTO-VENDITA") -> 0 | P5: =SUMIFS(INDIRECT("'" & P$4 & "'!$I$11:$I$1000"), INDIRECT("'" & P$4 & "'!$G$11:$G$1000"), $E5, INDIRECT("'" & P$4 & "'!$A$11:$A$1000"), "INZIA IL TRATTAMENTO-VENDITA") -> 0 | Q5: =SUMIFS(INDIRECT("'" & Q$4 & "'!$I$11:$I$1000"), INDIRECT("'" & Q$4 & "'!$G$11:$G$1000"), $E5, INDIRECT("'" & Q$4 & "'!$A$11:$A$1000"), "INZIA IL TRATTAMENTO-VENDITA") -> 0 | R5: =SUM(C5:Q5) -> 80935
B6: AMOROSO | C6: =SUMIFS('OPPORTUNITA DI VENDITA'!$J$198:$J$1000, 'OPPORTUNITA DI VENDITA'!$H$198:$H$1000, B6, 'OPPORTUNITA DI VENDITA'!$B$198:$B$1000, "ESEGUITO") -> 25388 | E6: AMOROSO | F6: =SUMIFS(INDIRECT("'" & $F$4 & "'!$I$11:$I$1000"), INDIRECT("'" & $F$4 & "'!$G$11:$G$1000"), $E6, INDIRECT("'" & $F$4 & "'!$A$11:$A$1000"), "INZIA IL TRATTAMENTO-VENDITA") -> 2280 | G6: =SUMIFS(INDIRECT("'" & $G$4 & "'!$I$11:$I$1000"), INDIRECT("'" & $G$4 & "'!$G$11:$G$1000"), $E6, INDIRECT("'" & $G$4 & "'!$A$11:$A$1000"), "INZIA IL TRATTAMENTO-VENDITA") -> 18963 | H6: =SUMIFS(INDIRECT("'" & $H$4 & "'!$I$11:$I$1000"), INDIRECT("'" & $H$4 & "'!$G$11:$G$1000"), $E6, INDIRECT("'" & $H$4 & "'!$A$11:$A$1000"), "INZIA IL TRATTAMENTO-VENDITA") -> 21116 | I6: =SUMIFS(INDIRECT("'" & $I$4 & "'!$I$11:$I$1000"), INDIRECT("'" & $I$4 & "'!$G$11:$G$1000"), $E6, INDIRECT("'" & $I$4 & "'!$A$11:$A$1000"), "INZIA IL TRATTAMENTO-VENDITA") -> 17210 | J6: =SUMIFS(INDIRECT("'" & J$4 & "'!$I$11:$I$1000"), INDIRECT("'" & J$4 & "'!$G$11:$G$1000"), $E6, INDIRECT("'" & J$4 & "'!$A$11:$A$1000"), "INZIA IL TRATTAMENTO-VENDITA") -> 14170 | K6: =SUMIFS(INDIRECT("'" & K$4 & "'!$I$11:$I$1000"), INDIRECT("'" & K$4 & "'!$G$11:$G$1000"), $E6, INDIRECT("'" & K$4 & "'!$A$11:$A$1000"), "INZIA IL TRATTAMENTO-VENDITA") -> 11970 | L6: =SUMIFS(INDIRECT("'" & L$4 & "'!$I$11:$I$1000"), INDIRECT("'" & L$4 & "'!$G$11:$G$1000"), $E6, INDIRECT("'" & L$4 & "'!$A$11:$A$1000"), "INZIA IL TRATTAMENTO-VENDITA") -> 0 | M6: =SUMIFS(INDIRECT("'" & M$4 & "'!$I$11:$I$1000"), INDIRECT("'" & M$4 & "'!$G$11:$G$1000"), $E6, INDIRECT("'" & M$4 & "'!$A$11:$A$1000"), "INZIA IL TRATTAMENTO-VENDITA") -> 0 | N6: =SUMIFS(INDIRECT("'" & N$4 & "'!$I$11:$I$1000"), INDIRECT("'" & N$4 & "'!$G$11:$G$1000"), $E6, INDIRECT("'" & N$4 & "'!$A$11:$A$1000"), "INZIA IL TRATTAMENTO-VENDITA") -> 0 | O6: =SUMIFS(INDIRECT("'" & O$4 & "'!$I$11:$I$1000"), INDIRECT("'" & O$4 & "'!$G$11:$G$1000"), $E6, INDIRECT("'" & O$4 & "'!$A$11:$A$1000"), "INZIA IL TRATTAMENTO-VENDITA") -> 0 | P6: =SUMIFS(INDIRECT("'" & P$4 & "'!$I$11:$I$1000"), INDIRECT("'" & P$4 & "'!$G$11:$G$1000"), $E6, INDIRECT("'" & P$4 & "'!$A$11:$A$1000"), "INZIA IL TRATTAMENTO-VENDITA") -> 0 | Q6: =SUMIFS(INDIRECT("'" & Q$4 & "'!$I$11:$I$1000"), INDIRECT("'" & Q$4 & "'!$G$11:$G$1000"), $E6, INDIRECT("'" & Q$4 & "'!$A$11:$A$1000"), "INZIA IL TRATTAMENTO-VENDITA") -> 0 | R6: =SUM(C6:Q6) -> 111097
B7: INNOCENTE | C7: =SUMIFS('OPPORTUNITA DI VENDITA'!$J$198:$J$1000, 'OPPORTUNITA DI VENDITA'!$H$198:$H$1000, B7, 'OPPORTUNITA DI VENDITA'!$B$198:$B$1000, "ESEGUITO") -> 0 | E7: INNOCENTE | F7: =SUMIFS(INDIRECT("'" & $F$4 & "'!$I$11:$I$1000"), INDIRECT("'" & $F$4 & "'!$G$11:$G$1000"), $E7, INDIRECT("'" & $F$4 & "'!$A$11:$A$1000"), "INZIA IL TRATTAMENTO-VENDITA") -> 0 | G7: =SUMIFS(INDIRECT("'" & $G$4 & "'!$I$11:$I$1000"), INDIRECT("'" & $G$4 & "'!$G$11:$G$1000"), $E7, INDIRECT("'" & $G$4 & "'!$A$11:$A$1000"), "INZIA IL TRATTAMENTO-VENDITA") -> 0 | H7: =SUMIFS(INDIRECT("'" & $H$4 & "'!$I$11:$I$1000"), INDIRECT("'" & $H$4 & "'!$G$11:$G$1000"), $E7, INDIRECT("'" & $H$4 & "'!$A$11:$A$1000"), "INZIA IL TRATTAMENTO-VENDITA") -> 770 | I7: =SUMIFS(INDIRECT("'" & $I$4 & "'!$I$11:$I$1000"), INDIRECT("'" & $I$4 & "'!$G$11:$G$1000"), $E7, INDIRECT("'" & $I$4 & "'!$A$11:$A$1000"), "INZIA IL TRATTAMENTO-VENDITA") -> 0 | J7: =SUMIFS(INDIRECT("'" & J$4 & "'!$I$11:$I$1000"), INDIRECT("'" & J$4 & "'!$G$11:$G$1000"), $E7, INDIRECT("'" & J$4 & "'!$A$11:$A$1000"), "INZIA IL TRATTAMENTO-VENDITA") -> 0 | K7: =SUMIFS(INDIRECT("'" & K$4 & "'!$I$11:$I$1000"), INDIRECT("'" & K$4 & "'!$G$11:$G$1000"), $E7, INDIRECT("'" & K$4 & "'!$A$11:$A$1000"), "INZIA IL TRATTAMENTO-VENDITA") -> 0 | L7: =SUMIFS(INDIRECT("'" & L$4 & "'!$I$11:$I$1000"), INDIRECT("'" & L$4 & "'!$G$11:$G$1000"), $E7, INDIRECT("'" & L$4 & "'!$A$11:$A$1000"), "INZIA IL TRATTAMENTO-VENDITA") -> 0 | M7: =SUMIFS(INDIRECT("'" & M$4 & "'!$I$11:$I$1000"), INDIRECT("'" & M$4 & "'!$G$11:$G$1000"), $E7, INDIRECT("'" & M$4 & "'!$A$11:$A$1000"), "INZIA IL TRATTAMENTO-VENDITA") -> 0 | N7: =SUMIFS(INDIRECT("'" & N$4 & "'!$I$11:$I$1000"), INDIRECT("'" & N$4 & "'!$G$11:$G$1000"), $E7, INDIRECT("'" & N$4 & "'!$A$11:$A$1000"), "INZIA IL TRATTAMENTO-VENDITA") -> 0 | O7: =SUMIFS(INDIRECT("'" & O$4 & "'!$I$11:$I$1000"), INDIRECT("'" & O$4 & "'!$G$11:$G$1000"), $E7, INDIRECT("'" & O$4 & "'!$A$11:$A$1000"), "INZIA IL TRATTAMENTO-VENDITA") -> 0 | P7: =SUMIFS(INDIRECT("'" & P$4 & "'!$I$11:$I$1000"), INDIRECT("'" & P$4 & "'!$G$11:$G$1000"), $E7, INDIRECT("'" & P$4 & "'!$A$11:$A$1000"), "INZIA IL TRATTAMENTO-VENDITA") -> 0 | Q7: =SUMIFS(INDIRECT("'" & Q$4 & "'!$I$11:$I$1000"), INDIRECT("'" & Q$4 & "'!$G$11:$G$1000"), $E7, INDIRECT("'" & Q$4 & "'!$A$11:$A$1000"), "INZIA IL TRATTAMENTO-VENDITA") -> 0 | R7: =SUM(C7:Q7) -> 770
B8: BERARDI | C8: =SUMIFS('OPPORTUNITA DI VENDITA'!$J$198:$J$1000, 'OPPORTUNITA DI VENDITA'!$H$198:$H$1000, B8, 'OPPORTUNITA DI VENDITA'!$B$198:$B$1000, "ESEGUITO") -> 0 | E8: BERARDI | F8: =SUMIFS(INDIRECT("'" & $F$4 & "'!$I$11:$I$1000"), INDIRECT("'" & $F$4 & "'!$G$11:$G$1000"), $E8, INDIRECT("'" & $F$4 & "'!$A$11:$A$1000"), "INZIA IL TRATTAMENTO-VENDITA") -> 0 | G8: =SUMIFS(INDIRECT("'" & $G$4 & "'!$I$11:$I$1000"), INDIRECT("'" & $G$4 & "'!$G$11:$G$1000"), $E8, INDIRECT("'" & $G$4 & "'!$A$11:$A$1000"), "INZIA IL TRATTAMENTO-VENDITA") -> 0 | H8: =SUMIFS(INDIRECT("'" & $H$4 & "'!$I$11:$I$1000"), INDIRECT("'" & $H$4 & "'!$G$11:$G$1000"), $E8, INDIRECT("'" & $H$4 & "'!$A$11:$A$1000"), "INZIA IL TRATTAMENTO-VENDITA") -> 0 | I8: =SUMIFS(INDIRECT("'" & $I$4 & "'!$I$11:$I$1000"), INDIRECT("'" & $I$4 & "'!$G$11:$G$1000"), $E8, INDIRECT("'" & $I$4 & "'!$A$11:$A$1000"), "INZIA IL TRATTAMENTO-VENDITA") -> 0 | J8: =SUMIFS(INDIRECT("'" & J$4 & "'!$I$11:$I$1000"), INDIRECT("'" & J$4 & "'!$G$11:$G$1000"), $E8, INDIRECT("'" & J$4 & "'!$A$11:$A$1000"), "INZIA IL TRATTAMENTO-VENDITA") -> 0 | K8: =SUMIFS(INDIRECT("'" & K$4 & "'!$I$11:$I$1000"), INDIRECT("'" & K$4 & "'!$G$11:$G$1000"), $E8, INDIRECT("'" & K$4 & "'!$A$11:$A$1000"), "INZIA IL TRATTAMENTO-VENDITA") -> 0 | L8: =SUMIFS(INDIRECT("'" & L$4 & "'!$I$11:$I$1000"), INDIRECT("'" & L$4 & "'!$G$11:$G$1000"), $E8, INDIRECT("'" & L$4 & "'!$A$11:$A$1000"), "INZIA IL TRATTAMENTO-VENDITA") -> 0 | M8: =SUMIFS(INDIRECT("'" & M$4 & "'!$I$11:$I$1000"), INDIRECT("'" & M$4 & "'!$G$11:$G$1000"), $E8, INDIRECT("'" & M$4 & "'!$A$11:$A$1000"), "INZIA IL TRATTAMENTO-VENDITA") -> 0 | N8: =SUMIFS(INDIRECT("'" & N$4 & "'!$I$11:$I$1000"), INDIRECT("'" & N$4 & "'!$G$11:$G$1000"), $E8, INDIRECT("'" & N$4 & "'!$A$11:$A$1000"), "INZIA IL TRATTAMENTO-VENDITA") -> 0 | O8: =SUMIFS(INDIRECT("'" & O$4 & "'!$I$11:$I$1000"), INDIRECT("'" & O$4 & "'!$G$11:$G$1000"), $E8, INDIRECT("'" & O$4 & "'!$A$11:$A$1000"), "INZIA IL TRATTAMENTO-VENDITA") -> 0 | P8: =SUMIFS(INDIRECT("'" & P$4 & "'!$I$11:$I$1000"), INDIRECT("'" & P$4 & "'!$G$11:$G$1000"), $E8, INDIRECT("'" & P$4 & "'!$A$11:$A$1000"), "INZIA IL TRATTAMENTO-VENDITA") -> 0 | Q8: =SUMIFS(INDIRECT("'" & Q$4 & "'!$I$11:$I$1000"), INDIRECT("'" & Q$4 & "'!$G$11:$G$1000"), $E8, INDIRECT("'" & Q$4 & "'!$A$11:$A$1000"), "INZIA IL TRATTAMENTO-VENDITA") -> 0 | R8: =SUM(C8:Q8) -> 0
B9: BERNARDINI | C9: =SUMIFS('OPPORTUNITA DI VENDITA'!$J$198:$J$1000, 'OPPORTUNITA DI VENDITA'!$H$198:$H$1000, B9, 'OPPORTUNITA DI VENDITA'!$B$198:$B$1000, "ESEGUITO") -> 0 | E9: BERNARDINI | F9: =SUMIFS(INDIRECT("'" & $F$4 & "'!$I$11:$I$1000"), INDIRECT("'" & $F$4 & "'!$G$11:$G$1000"), $E9, INDIRECT("'" & $F$4 & "'!$A$11:$A$1000"), "INZIA IL TRATTAMENTO-VENDITA") -> 0 | G9: =SUMIFS(INDIRECT("'" & $G$4 & "'!$I$11:$I$1000"), INDIRECT("'" & $G$4 & "'!$G$11:$G$1000"), $E9, INDIRECT("'" & $G$4 & "'!$A$11:$A$1000"), "INZIA IL TRATTAMENTO-VENDITA") -> 0 | H9: =SUMIFS(INDIRECT("'" & $H$4 & "'!$I$11:$I$1000"), INDIRECT("'" & $H$4 & "'!$G$11:$G$1000"), $E9, INDIRECT("'" & $H$4 & "'!$A$11:$A$1000"), "INZIA IL TRATTAMENTO-VENDITA") -> 0 | I9: =SUMIFS(INDIRECT("'" & $I$4 & "'!$I$11:$I$1000"), INDIRECT("'" & $I$4 & "'!$G$11:$G$1000"), $E9, INDIRECT("'" & $I$4 & "'!$A$11:$A$1000"), "INZIA IL TRATTAMENTO-VENDITA") -> 0 | J9: =SUMIFS(INDIRECT("'" & J$4 & "'!$I$11:$I$1000"), INDIRECT("'" & J$4 & "'!$G$11:$G$1000"), $E9, INDIRECT("'" & J$4 & "'!$A$11:$A$1000"), "INZIA IL TRATTAMENTO-VENDITA") -> 0 | K9: =SUMIFS(INDIRECT("'" & K$4 & "'!$I$11:$I$1000"), INDIRECT("'" & K$4 & "'!$G$11:$G$1000"), $E9, INDIRECT("'" & K$4 & "'!$A$11:$A$1000"), "INZIA IL TRATTAMENTO-VENDITA") -> 0 | L9: =SUMIFS(INDIRECT("'" & L$4 & "'!$I$11:$I$1000"), INDIRECT("'" & L$4 & "'!$G$11:$G$1000"), $E9, INDIRECT("'" & L$4 & "'!$A$11:$A$1000"), "INZIA IL TRATTAMENTO-VENDITA") -> 0 | M9: =SUMIFS(INDIRECT("'" & M$4 & "'!$I$11:$I$1000"), INDIRECT("'" & M$4 & "'!$G$11:$G$1000"), $E9, INDIRECT("'" & M$4 & "'!$A$11:$A$1000"), "INZIA IL TRATTAMENTO-VENDITA") -> 0 | N9: =SUMIFS(INDIRECT("'" & N$4 & "'!$I$11:$I$1000"), INDIRECT("'" & N$4 & "'!$G$11:$G$1000"), $E9, INDIRECT("'" & N$4 & "'!$A$11:$A$1000"), "INZIA IL TRATTAMENTO-VENDITA") -> 0 | O9: =SUMIFS(INDIRECT("'" & O$4 & "'!$I$11:$I$1000"), INDIRECT("'" & O$4 & "'!$G$11:$G$1000"), $E9, INDIRECT("'" & O$4 & "'!$A$11:$A$1000"), "INZIA IL TRATTAMENTO-VENDITA") -> 0 | P9: =SUMIFS(INDIRECT("'" & P$4 & "'!$I$11:$I$1000"), INDIRECT("'" & P$4 & "'!$G$11:$G$1000"), $E9, INDIRECT("'" & P$4 & "'!$A$11:$A$1000"), "INZIA IL TRATTAMENTO-VENDITA") -> 0 | Q9: =SUMIFS(INDIRECT("'" & Q$4 & "'!$I$11:$I$1000"), INDIRECT("'" & Q$4 & "'!$G$11:$G$1000"), $E9, INDIRECT("'" & Q$4 & "'!$A$11:$A$1000"), "INZIA IL TRATTAMENTO-VENDITA") -> 0 | R9: =SUM(C9:Q9) -> 0
B10: MASTRORILLI | C10: =SUMIFS('OPPORTUNITA DI VENDITA'!$J$198:$J$1000, 'OPPORTUNITA DI VENDITA'!$H$198:$H$1000, B10, 'OPPORTUNITA DI VENDITA'!$B$198:$B$1000, "ESEGUITO") -> 0 | E10: MASTRORILLI | F10: =SUMIFS(INDIRECT("'" & $F$4 & "'!$I$11:$I$1000"), INDIRECT("'" & $F$4 & "'!$G$11:$G$1000"), $E10, INDIRECT("'" & $F$4 & "'!$A$11:$A$1000"), "INZIA IL TRATTAMENTO-VENDITA") -> 0 | G10: =SUMIFS(INDIRECT("'" & $G$4 & "'!$I$11:$I$1000"), INDIRECT("'" & $G$4 & "'!$G$11:$G$1000"), $E10, INDIRECT("'" & $G$4 & "'!$A$11:$A$1000"), "INZIA IL TRATTAMENTO-VENDITA") -> 0 | H10: =SUMIFS(INDIRECT("'" & $H$4 & "'!$I$11:$I$1000"), INDIRECT("'" & $H$4 & "'!$G$11:$G$1000"), $E10, INDIRECT("'" & $H$4 & "'!$A$11:$A$1000"), "INZIA IL TRATTAMENTO-VENDITA") -> 0 | I10: =SUMIFS(INDIRECT("'" & $I$4 & "'!$I$11:$I$1000"), INDIRECT("'" & $I$4 & "'!$G$11:$G$1000"), $E10, INDIRECT("'" & $I$4 & "'!$A$11:$A$1000"), "INZIA IL TRATTAMENTO-VENDITA") -> 759 | J10: =SUMIFS(INDIRECT("'" & J$4 & "'!$I$11:$I$1000"), INDIRECT("'" & J$4 & "'!$G$11:$G$1000"), $E10, INDIRECT("'" & J$4 & "'!$A$11:$A$1000"), "INZIA IL TRATTAMENTO-VENDITA") -> 100 | K10: =SUMIFS(INDIRECT("'" & K$4 & "'!$I$11:$I$1000"), INDIRECT("'" & K$4 & "'!$G$11:$G$1000"), $E10, INDIRECT("'" & K$4 & "'!$A$11:$A$1000"), "INZIA IL TRATTAMENTO-VENDITA") -> 640 | L10: =SUMIFS(INDIRECT("'" & L$4 & "'!$I$11:$I$1000"), INDIRECT("'" & L$4 & "'!$G$11:$G$1000"), $E10, INDIRECT("'" & L$4 & "'!$A$11:$A$1000"), "INZIA IL TRATTAMENTO-VENDITA") -> 0 | M10: =SUMIFS(INDIRECT("'" & M$4 & "'!$I$11:$I$1000"), INDIRECT("'" & M$4 & "'!$G$11:$G$1000"), $E10, INDIRECT("'" & M$4 & "'!$A$11:$A$1000"), "INZIA IL TRATTAMENTO-VENDITA") -> 0 | N10: =SUMIFS(INDIRECT("'" & N$4 & "'!$I$11:$I$1000"), INDIRECT("'" & N$4 & "'!$G$11:$G$1000"), $E10, INDIRECT("'" & N$4 & "'!$A$11:$A$1000"), "INZIA IL TRATTAMENTO-VENDITA") -> 0 | O10: =SUMIFS(INDIRECT("'" & O$4 & "'!$I$11:$I$1000"), INDIRECT("'" & O$4 & "'!$G$11:$G$1000"), $E10, INDIRECT("'" & O$4 & "'!$A$11:$A$1000"), "INZIA IL TRATTAMENTO-VENDITA") -> 0 | P10: =SUMIFS(INDIRECT("'" & P$4 & "'!$I$11:$I$1000"), INDIRECT("'" & P$4 & "'!$G$11:$G$1000"), $E10, INDIRECT("'" & P$4 & "'!$A$11:$A$1000"), "INZIA IL TRATTAMENTO-VENDITA") -> 0 | Q10: =SUMIFS(INDIRECT("'" & Q$4 & "'!$I$11:$I$1000"), INDIRECT("'" & Q$4 & "'!$G$11:$G$1000"), $E10, INDIRECT("'" & Q$4 & "'!$A$11:$A$1000"), "INZIA IL TRATTAMENTO-VENDITA") -> 0 | R10: =SUM(C10:Q10) -> 1499
B11: CARDONE | C11: =SUMIFS('OPPORTUNITA DI VENDITA'!$J$198:$J$1000, 'OPPORTUNITA DI VENDITA'!$H$198:$H$1000, B11, 'OPPORTUNITA DI VENDITA'!$B$198:$B$1000, "ESEGUITO") -> 0 | E11: CARDONE | F11: =SUMIFS(INDIRECT("'" & $F$4 & "'!$I$11:$I$1000"), INDIRECT("'" & $F$4 & "'!$G$11:$G$1000"), $E11, INDIRECT("'" & $F$4 & "'!$A$11:$A$1000"), "INZIA IL TRATTAMENTO-VENDITA") -> 7785 | G11: =SUMIFS(INDIRECT("'" & $G$4 & "'!$I$11:$I$1000"), INDIRECT("'" & $G$4 & "'!$G$11:$G$1000"), $E11, INDIRECT("'" & $G$4 & "'!$A$11:$A$1000"), "INZIA IL TRATTAMENTO-VENDITA") -> 0 | H11: =SUMIFS(INDIRECT("'" & $H$4 & "'!$I$11:$I$1000"), INDIRECT("'" & $H$4 & "'!$G$11:$G$1000"), $E11, INDIRECT("'" & $H$4 & "'!$A$11:$A$1000"), "INZIA IL TRATTAMENTO-VENDITA") -> 11520 | I11: =SUMIFS(INDIRECT("'" & $I$4 & "'!$I$11:$I$1000"), INDIRECT("'" & $I$4 & "'!$G$11:$G$1000"), $E11, INDIRECT("'" & $I$4 & "'!$A$11:$A$1000"), "INZIA IL TRATTAMENTO-VENDITA") -> 4191 | J11: =SUMIFS(INDIRECT("'" & J$4 & "'!$I$11:$I$1000"), INDIRECT("'" & J$4 & "'!$G$11:$G$1000"), $E11, INDIRECT("'" & J$4 & "'!$A$11:$A$1000"), "INZIA IL TRATTAMENTO-VENDITA") -> 0 | K11: =SUMIFS(INDIRECT("'" & K$4 & "'!$I$11:$I$1000"), INDIRECT("'" & K$4 & "'!$G$11:$G$1000"), $E11, INDIRECT("'" & K$4 & "'!$A$11:$A$1000"), "INZIA IL TRATTAMENTO-VENDITA") -> 4590 | L11: =SUMIFS(INDIRECT("'" & L$4 & "'!$I$11:$I$1000"), INDIRECT("'" & L$4 & "'!$G$11:$G$1000"), $E11, INDIRECT("'" & L$4 & "'!$A$11:$A$1000"), "INZIA IL TRATTAMENTO-VENDITA") -> 0 | M11: =SUMIFS(INDIRECT("'" & M$4 & "'!$I$11:$I$1000"), INDIRECT("'" & M$4 & "'!$G$11:$G$1000"), $E11, INDIRECT("'" & M$4 & "'!$A$11:$A$1000"), "INZIA IL TRATTAMENTO-VENDITA") -> 0 | N11: =SUMIFS(INDIRECT("'" & N$4 & "'!$I$11:$I$1000"), INDIRECT("'" & N$4 & "'!$G$11:$G$1000"), $E11, INDIRECT("'" & N$4 & "'!$A$11:$A$1000"), "INZIA IL TRATTAMENTO-VENDITA") -> 0 | O11: =SUMIFS(INDIRECT("'" & O$4 & "'!$I$11:$I$1000"), INDIRECT("'" & O$4 & "'!$G$11:$G$1000"), $E11, INDIRECT("'" & O$4 & "'!$A$11:$A$1000"), "INZIA IL TRATTAMENTO-VENDITA") -> 0 | P11: =SUMIFS(INDIRECT("'" & P$4 & "'!$I$11:$I$1000"), INDIRECT("'" & P$4 & "'!$G$11:$G$1000"), $E11, INDIRECT("'" & P$4 & "'!$A$11:$A$1000"), "INZIA IL TRATTAMENTO-VENDITA") -> 0 | Q11: =SUMIFS(INDIRECT("'" & Q$4 & "'!$I$11:$I$1000"), INDIRECT("'" & Q$4 & "'!$G$11:$G$1000"), $E11, INDIRECT("'" & Q$4 & "'!$A$11:$A$1000"), "INZIA IL TRATTAMENTO-VENDITA") -> 0 | R11: =SUM(C11:Q11) -> 28086
B12: MARCANTONI | C12: =SUMIFS('OPPORTUNITA DI VENDITA'!$J$198:$J$1000, 'OPPORTUNITA DI VENDITA'!$H$198:$H$1000, B12, 'OPPORTUNITA DI VENDITA'!$B$198:$B$1000, "ESEGUITO") -> 0 | E12: MARCANTONI | F12: =SUMIFS(INDIRECT("'" & $F$4 & "'!$I$11:$I$1000"), INDIRECT("'" & $F$4 & "'!$G$11:$G$1000"), $E12, INDIRECT("'" & $F$4 & "'!$A$11:$A$1000"), "INZIA IL TRATTAMENTO-VENDITA") -> 304 | G12: =SUMIFS(INDIRECT("'" & $G$4 & "'!$I$11:$I$1000"), INDIRECT("'" & $G$4 & "'!$G$11:$G$1000"), $E12, INDIRECT("'" & $G$4 & "'!$A$11:$A$1000"), "INZIA IL TRATTAMENTO-VENDITA") -> 240 | H12: =SUMIFS(INDIRECT("'" & $H$4 & "'!$I$11:$I$1000"), INDIRECT("'" & $H$4 & "'!$G$11:$G$1000"), $E12, INDIRECT("'" & $H$4 & "'!$A$11:$A$1000"), "INZIA IL TRATTAMENTO-VENDITA") -> 392 | I12: =SUMIFS(INDIRECT("'" & $I$4 & "'!$I$11:$I$1000"), INDIRECT("'" & $I$4 & "'!$G$11:$G$1000"), $E12, INDIRECT("'" & $I$4 & "'!$A$11:$A$1000"), "INZIA IL TRATTAMENTO-VENDITA") -> 0 | J12: =SUMIFS(INDIRECT("'" & J$4 & "'!$I$11:$I$1000"), INDIRECT("'" & J$4 & "'!$G$11:$G$1000"), $E12, INDIRECT("'" & J$4 & "'!$A$11:$A$1000"), "INZIA IL TRATTAMENTO-VENDITA") -> 205 | K12: =SUMIFS(INDIRECT("'" & K$4 & "'!$I$11:$I$1000"), INDIRECT("'" & K$4 & "'!$G$11:$G$1000"), $E12, INDIRECT("'" & K$4 & "'!$A$11:$A$1000"), "INZIA IL TRATTAMENTO-VENDITA") -> 100 | L12: =SUMIFS(INDIRECT("'" & L$4 & "'!$I$11:$I$1000"), INDIRECT("'" & L$4 & "'!$G$11:$G$1000"), $E12, INDIRECT("'" & L$4 & "'!$A$11:$A$1000"), "INZIA IL TRATTAMENTO-VENDITA") -> 0 | M12: =SUMIFS(INDIRECT("'" & M$4 & "'!$I$11:$I$1000"), INDIRECT("'" & M$4 & "'!$G$11:$G$1000"), $E12, INDIRECT("'" & M$4 & "'!$A$11:$A$1000"), "INZIA IL TRATTAMENTO-VENDITA") -> 0 | N12: =SUMIFS(INDIRECT("'" & N$4 & "'!$I$11:$I$1000"), INDIRECT("'" & N$4 & "'!$G$11:$G$1000"), $E12, INDIRECT("'" & N$4 & "'!$A$11:$A$1000"), "INZIA IL TRATTAMENTO-VENDITA") -> 0 | O12: =SUMIFS(INDIRECT("'" & O$4 & "'!$I$11:$I$1000"), INDIRECT("'" & O$4 & "'!$G$11:$G$1000"), $E12, INDIRECT("'" & O$4 & "'!$A$11:$A$1000"), "INZIA IL TRATTAMENTO-VENDITA") -> 0 | P12: =SUMIFS(INDIRECT("'" & P$4 & "'!$I$11:$I$1000"), INDIRECT("'" & P$4 & "'!$G$11:$G$1000"), $E12, INDIRECT("'" & P$4 & "'!$A$11:$A$1000"), "INZIA IL TRATTAMENTO-VENDITA") -> 0 | Q12: =SUMIFS(INDIRECT("'" & Q$4 & "'!$I$11:$I$1000"), INDIRECT("'" & Q$4 & "'!$G$11:$G$1000"), $E12, INDIRECT("'" & Q$4 & "'!$A$11:$A$1000"), "INZIA IL TRATTAMENTO-VENDITA") -> 0 | R12: =SUM(C12:Q12) -> 1241
B13: MIRACOLO | C13: =SUMIFS('OPPORTUNITA DI VENDITA'!$J$198:$J$1000, 'OPPORTUNITA DI VENDITA'!$H$198:$H$1000, B13, 'OPPORTUNITA DI VENDITA'!$B$198:$B$1000, "ESEGUITO") -> 10844 | E13: MIRACOLO | F13: =SUMIFS(INDIRECT("'" & $F$4 & "'!$I$11:$I$1000"), INDIRECT("'" & $F$4 & "'!$G$11:$G$1000"), $E13, INDIRECT("'" & $F$4 & "'!$A$11:$A$1000"), "INZIA IL TRATTAMENTO-VENDITA") -> 0 | G13: =SUMIFS(INDIRECT("'" & $G$4 & "'!$I$11:$I$1000"), INDIRECT("'" & $G$4 & "'!$G$11:$G$1000"), $E13, INDIRECT("'" & $G$4 & "'!$A$11:$A$1000"), "INZIA IL TRATTAMENTO-VENDITA") -> 70 | H13: =SUMIFS(INDIRECT("'" & $H$4 & "'!$I$11:$I$1000"), INDIRECT("'" & $H$4 & "'!$G$11:$G$1000"), $E13, INDIRECT("'" & $H$4 & "'!$A$11:$A$1000"), "INZIA IL TRATTAMENTO-VENDITA") -> 10250 | I13: =SUMIFS(INDIRECT("'" & $I$4 & "'!$I$11:$I$1000"), INDIRECT("'" & $I$4 & "'!$G$11:$G$1000"), $E13, INDIRECT("'" & $I$4 & "'!$A$11:$A$1000"), "INZIA IL TRATTAMENTO-VENDITA") -> 0 | J13: =SUMIFS(INDIRECT("'" & J$4 & "'!$I$11:$I$1000"), INDIRECT("'" & J$4 & "'!$G$11:$G$1000"), $E13, INDIRECT("'" & J$4 & "'!$A$11:$A$1000"), "INZIA IL TRATTAMENTO-VENDITA") -> 2103 | K13: =SUMIFS(INDIRECT("'" & K$4 & "'!$I$11:$I$1000"), INDIRECT("'" & K$4 & "'!$G$11:$G$1000"), $E13, INDIRECT("'" & K$4 & "'!$A$11:$A$1000"), "INZIA IL TRATTAMENTO-VENDITA") -> 1450 | L13: =SUMIFS(INDIRECT("'" & L$4 & "'!$I$11:$I$1000"), INDIRECT("'" & L$4 & "'!$G$11:$G$1000"), $E13, INDIRECT("'" & L$4 & "'!$A$11:$A$1000"), "INZIA IL TRATTAMENTO-VENDITA") -> 0 | M13: =SUMIFS(INDIRECT("'" & M$4 & "'!$I$11:$I$1000"), INDIRECT("'" & M$4 & "'!$G$11:$G$1000"), $E13, INDIRECT("'" & M$4 & "'!$A$11:$A$1000"), "INZIA IL TRATTAMENTO-VENDITA") -> 0 | N13: =SUMIFS(INDIRECT("'" & N$4 & "'!$I$11:$I$1000"), INDIRECT("'" & N$4 & "'!$G$11:$G$1000"), $E13, INDIRECT("'" & N$4 & "'!$A$11:$A$1000"), "INZIA IL TRATTAMENTO-VENDITA") -> 0 | O13: =SUMIFS(INDIRECT("'" & O$4 & "'!$I$11:$I$1000"), INDIRECT("'" & O$4 & "'!$G$11:$G$1000"), $E13, INDIRECT("'" & O$4 & "'!$A$11:$A$1000"), "INZIA IL TRATTAMENTO-VENDITA") -> 0 | P13: =SUMIFS(INDIRECT("'" & P$4 & "'!$I$11:$I$1000"), INDIRECT("'" & P$4 & "'!$G$11:$G$1000"), $E13, INDIRECT("'" & P$4 & "'!$A$11:$A$1000"), "INZIA IL TRATTAMENTO-VENDITA") -> 0 | Q13: =SUMIFS(INDIRECT("'" & Q$4 & "'!$I$11:$I$1000"), INDIRECT("'" & Q$4 & "'!$G$11:$G$1000"), $E13, INDIRECT("'" & Q$4 & "'!$A$11:$A$1000"), "INZIA IL TRATTAMENTO-VENDITA") -> 0 | R13: =SUM(C13:Q13) -> 24717
B14: MAZZELLI | C14: =SUMIFS('OPPORTUNITA DI VENDITA'!$J$198:$J$1000, 'OPPORTUNITA DI VENDITA'!$H$198:$H$1000, B14, 'OPPORTUNITA DI VENDITA'!$B$198:$B$1000, "ESEGUITO") -> 0 | E14: MAZZELLI | F14: =SUMIFS(INDIRECT("'" & $F$4 & "'!$I$11:$I$1000"), INDIRECT("'" & $F$4 & "'!$G$11:$G$1000"), $E14, INDIRECT("'" & $F$4 & "'!$A$11:$A$1000"), "INZIA IL TRATTAMENTO-VENDITA") -> 21830 | G14: =SUMIFS(INDIRECT("'" & $G$4 & "'!$I$11:$I$1000"), INDIRECT("'" & $G$4 & "'!$G$11:$G$1000"), $E14, INDIRECT("'" & $G$4 & "'!$A$11:$A$1000"), "INZIA IL TRATTAMENTO-VENDITA") -> 22358 | H14: =SUMIFS(INDIRECT("'" & $H$4 & "'!$I$11:$I$1000"), INDIRECT("'" & $H$4 & "'!$G$11:$G$1000"), $E14, INDIRECT("'" & $H$4 & "'!$A$11:$A$1000"), "INZIA IL TRATTAMENTO-VENDITA") -> 7900 | I14: =SUMIFS(INDIRECT("'" & $I$4 & "'!$I$11:$I$1000"), INDIRECT("'" & $I$4 & "'!$G$11:$G$1000"), $E14, INDIRECT("'" & $I$4 & "'!$A$11:$A$1000"), "INZIA IL TRATTAMENTO-VENDITA") -> 1055 | J14: =SUMIFS(INDIRECT("'" & J$4 & "'!$I$11:$I$1000"), INDIRECT("'" & J$4 & "'!$G$11:$G$1000"), $E14, INDIRECT("'" & J$4 & "'!$A$11:$A$1000"), "INZIA IL TRATTAMENTO-VENDITA") -> 17001 | K14: =SUMIFS(INDIRECT("'" & K$4 & "'!$I$11:$I$1000"), INDIRECT("'" & K$4 & "'!$G$11:$G$1000"), $E14, INDIRECT("'" & K$4 & "'!$A$11:$A$1000"), "INZIA IL TRATTAMENTO-VENDITA") -> 0 | L14: =SUMIFS(INDIRECT("'" & L$4 & "'!$I$11:$I$1000"), INDIRECT("'" & L$4 & "'!$G$11:$G$1000"), $E14, INDIRECT("'" & L$4 & "'!$A$11:$A$1000"), "INZIA IL TRATTAMENTO-VENDITA") -> 0 | M14: =SUMIFS(INDIRECT("'" & M$4 & "'!$I$11:$I$1000"), INDIRECT("'" & M$4 & "'!$G$11:$G$1000"), $E14, INDIRECT("'" & M$4 & "'!$A$11:$A$1000"), "INZIA IL TRATTAMENTO-VENDITA") -> 0 | N14: =SUMIFS(INDIRECT("'" & N$4 & "'!$I$11:$I$1000"), INDIRECT("'" & N$4 & "'!$G$11:$G$1000"), $E14, INDIRECT("'" & N$4 & "'!$A$11:$A$1000"), "INZIA IL TRATTAMENTO-VENDITA") -> 0 | O14: =SUMIFS(INDIRECT("'" & O$4 & "'!$I$11:$I$1000"), INDIRECT("'" & O$4 & "'!$G$11:$G$1000"), $E14, INDIRECT("'" & O$4 & "'!$A$11:$A$1000"), "INZIA IL TRATTAMENTO-VENDITA") -> 0 | P14: =SUMIFS(INDIRECT("'" & P$4 & "'!$I$11:$I$1000"), INDIRECT("'" & P$4 & "'!$G$11:$G$1000"), $E14, INDIRECT("'" & P$4 & "'!$A$11:$A$1000"), "INZIA IL TRATTAMENTO-VENDITA") -> 0 | Q14: =SUMIFS(INDIRECT("'" & Q$4 & "'!$I$11:$I$1000"), INDIRECT("'" & Q$4 & "'!$G$11:$G$1000"), $E14, INDIRECT("'" & Q$4 & "'!$A$11:$A$1000"), "INZIA IL TRATTAMENTO-VENDITA") -> 0 | R14: =SUM(C14:Q14) -> 70144
B15: GAGLIARDI | C15: =SUMIFS('OPPORTUNITA DI VENDITA'!$J$198:$J$1000, 'OPPORTUNITA DI VENDITA'!$H$198:$H$1000, B15, 'OPPORTUNITA DI VENDITA'!$B$198:$B$1000, "ESEGUITO") -> 0 | E15: GAGLIARDI | F15: =SUMIFS(INDIRECT("'" & $F$4 & "'!$I$11:$I$1000"), INDIRECT("'" & $F$4 & "'!$G$11:$G$1000"), $E15, INDIRECT("'" & $F$4 & "'!$A$11:$A$1000"), "INZIA IL TRATTAMENTO-VENDITA") -> 0 | G15: =SUMIFS(INDIRECT("'" & $G$4 & "'!$I$11:$I$1000"), INDIRECT("'" & $G$4 & "'!$G$11:$G$1000"), $E15, INDIRECT("'" & $G$4 & "'!$A$11:$A$1000"), "INZIA IL TRATTAMENTO-VENDITA") -> 0 | H15: =SUMIFS(INDIRECT("'" & $H$4 & "'!$I$11:$I$1000"), INDIRECT("'" & $H$4 & "'!$G$11:$G$1000"), $E15, INDIRECT("'" & $H$4 & "'!$A$11:$A$1000"), "INZIA IL TRATTAMENTO-VENDITA") -> 0 | I15: =SUMIFS(INDIRECT("'" & $I$4 & "'!$I$11:$I$1000"), INDIRECT("'" & $I$4 & "'!$G$11:$G$1000"), $E15, INDIRECT("'" & $I$4 & "'!$A$11:$A$1000"), "INZIA IL TRATTAMENTO-VENDITA") -> 0 | J15: =SUMIFS(INDIRECT("'" & J$4 & "'!$I$11:$I$1000"), INDIRECT("'" & J$4 & "'!$G$11:$G$1000"), $E15, INDIRECT("'" & J$4 & "'!$A$11:$A$1000"), "INZIA IL TRATTAMENTO-VENDITA") -> 0 | K15: =SUMIFS(INDIRECT("'" & K$4 & "'!$I$11:$I$1000"), INDIRECT("'" & K$4 & "'!$G$11:$G$1000"), $E15, INDIRECT("'" & K$4 & "'!$A$11:$A$1000"), "INZIA IL TRATTAMENTO-VENDITA") -> 0 | L15: =SUMIFS(INDIRECT("'" & L$4 & "'!$I$11:$I$1000"), INDIRECT("'" & L$4 & "'!$G$11:$G$1000"), $E15, INDIRECT("'" & L$4 & "'!$A$11:$A$1000"), "INZIA IL TRATTAMENTO-VENDITA") -> 0 | M15: =SUMIFS(INDIRECT("'" & M$4 & "'!$I$11:$I$1000"), INDIRECT("'" & M$4 & "'!$G$11:$G$1000"), $E15, INDIRECT("'" & M$4 & "'!$A$11:$A$1000"), "INZIA IL TRATTAMENTO-VENDITA") -> 0 | N15: =SUMIFS(INDIRECT("'" & N$4 & "'!$I$11:$I$1000"), INDIRECT("'" & N$4 & "'!$G$11:$G$1000"), $E15, INDIRECT("'" & N$4 & "'!$A$11:$A$1000"), "INZIA IL TRATTAMENTO-VENDITA") -> 0 | O15: =SUMIFS(INDIRECT("'" & O$4 & "'!$I$11:$I$1000"), INDIRECT("'" & O$4 & "'!$G$11:$G$1000"), $E15, INDIRECT("'" & O$4 & "'!$A$11:$A$1000"), "INZIA IL TRATTAMENTO-VENDITA") -> 0 | P15: =SUMIFS(INDIRECT("'" & P$4 & "'!$I$11:$I$1000"), INDIRECT("'" & P$4 & "'!$G$11:$G$1000"), $E15, INDIRECT("'" & P$4 & "'!$A$11:$A$1000"), "INZIA IL TRATTAMENTO-VENDITA") -> 0 | Q15: =SUMIFS(INDIRECT("'" & Q$4 & "'!$I$11:$I$1000"), INDIRECT("'" & Q$4 & "'!$G$11:$G$1000"), $E15, INDIRECT("'" & Q$4 & "'!$A$11:$A$1000"), "INZIA IL TRATTAMENTO-VENDITA") -> 0 | R15: =SUM(C15:Q15) -> 0
C16: =SUMIFS('OPPORTUNITA DI VENDITA'!$J$198:$J$1000, 'OPPORTUNITA DI VENDITA'!$H$198:$H$1000, B16, 'OPPORTUNITA DI VENDITA'!$B$198:$B$1000, "ESEGUITO") -> 0 | F16: =SUMIFS(INDIRECT("'" & $F$4 & "'!$I$11:$I$1000"), INDIRECT("'" & $F$4 & "'!$G$11:$G$1000"), $E16, INDIRECT("'" & $F$4 & "'!$A$11:$A$1000"), "INZIA IL TRATTAMENTO-VENDITA") -> 0 | G16: =SUMIFS(INDIRECT("'" & $G$4 & "'!$I$11:$I$1000"), INDIRECT("'" & $G$4 & "'!$G$11:$G$1000"), $E16, INDIRECT("'" & $G$4 & "'!$A$11:$A$1000"), "INZIA IL TRATTAMENTO-VENDITA") -> 0 | H16: =SUMIFS(INDIRECT("'" & $H$4 & "'!$I$11:$I$1000"), INDIRECT("'" & $H$4 & "'!$G$11:$G$1000"), $E16, INDIRECT("'" & $H$4 & "'!$A$11:$A$1000"), "INZIA IL TRATTAMENTO-VENDITA") -> 0 | I16: =SUMIFS(INDIRECT("'" & $I$4 & "'!$I$11:$I$1000"), INDIRECT("'" & $I$4 & "'!$G$11:$G$1000"), $E16, INDIRECT("'" & $I$4 & "'!$A$11:$A$1000"), "INZIA IL TRATTAMENTO-VENDITA") -> 0 | J16: =SUMIFS(INDIRECT("'" & J$4 & "'!$I$11:$I$1000"), INDIRECT("'" & J$4 & "'!$G$11:$G$1000"), $E16, INDIRECT("'" & J$4 & "'!$A$11:$A$1000"), "INZIA IL TRATTAMENTO-VENDITA") -> 0 | K16: =SUMIFS(INDIRECT("'" & K$4 & "'!$I$11:$I$1000"), INDIRECT("'" & K$4 & "'!$G$11:$G$1000"), $E16, INDIRECT("'" & K$4 & "'!$A$11:$A$1000"), "INZIA IL TRATTAMENTO-VENDITA") -> 0 | L16: =SUMIFS(INDIRECT("'" & L$4 & "'!$I$11:$I$1000"), INDIRECT("'" & L$4 & "'!$G$11:$G$1000"), $E16, INDIRECT("'" & L$4 & "'!$A$11:$A$1000"), "INZIA IL TRATTAMENTO-VENDITA") -> 0 | M16: =SUMIFS(INDIRECT("'" & M$4 & "'!$I$11:$I$1000"), INDIRECT("'" & M$4 & "'!$G$11:$G$1000"), $E16, INDIRECT("'" & M$4 & "'!$A$11:$A$1000"), "INZIA IL TRATTAMENTO-VENDITA") -> 0 | N16: =SUMIFS(INDIRECT("'" & N$4 & "'!$I$11:$I$1000"), INDIRECT("'" & N$4 & "'!$G$11:$G$1000"), $E16, INDIRECT("'" & N$4 & "'!$A$11:$A$1000"), "INZIA IL TRATTAMENTO-VENDITA") -> 0 | O16: =SUMIFS(INDIRECT("'" & O$4 & "'!$I$11:$I$1000"), INDIRECT("'" & O$4 & "'!$G$11:$G$1000"), $E16, INDIRECT("'" & O$4 & "'!$A$11:$A$1000"), "INZIA IL TRATTAMENTO-VENDITA") -> 0 | P16: =SUMIFS(INDIRECT("'" & P$4 & "'!$I$11:$I$1000"), INDIRECT("'" & P$4 & "'!$G$11:$G$1000"), $E16, INDIRECT("'" & P$4 & "'!$A$11:$A$1000"), "INZIA IL TRATTAMENTO-VENDITA") -> 0 | Q16: =SUMIFS(INDIRECT("'" & Q$4 & "'!$I$11:$I$1000"), INDIRECT("'" & Q$4 & "'!$G$11:$G$1000"), $E16, INDIRECT("'" & Q$4 & "'!$A$11:$A$1000"), "INZIA IL TRATTAMENTO-VENDITA") -> 0 | R16: =SUM(C16:Q16) -> 0
C17: =SUMIFS('OPPORTUNITA DI VENDITA'!$J$198:$J$1000, 'OPPORTUNITA DI VENDITA'!$H$198:$H$1000, B17, 'OPPORTUNITA DI VENDITA'!$B$198:$B$1000, "ESEGUITO") -> 0 | F17: =SUMIFS(INDIRECT("'" & $F$4 & "'!$I$11:$I$1000"), INDIRECT("'" & $F$4 & "'!$G$11:$G$1000"), $E17, INDIRECT("'" & $F$4 & "'!$A$11:$A$1000"), "INZIA IL TRATTAMENTO-VENDITA") -> 0 | G17: =SUMIFS(INDIRECT("'" & $G$4 & "'!$I$11:$I$1000"), INDIRECT("'" & $G$4 & "'!$G$11:$G$1000"), $E17, INDIRECT("'" & $G$4 & "'!$A$11:$A$1000"), "INZIA IL TRATTAMENTO-VENDITA") -> 0 | H17: =SUMIFS(INDIRECT("'" & $H$4 & "'!$I$11:$I$1000"), INDIRECT("'" & $H$4 & "'!$G$11:$G$1000"), $E17, INDIRECT("'" & $H$4 & "'!$A$11:$A$1000"), "INZIA IL TRATTAMENTO-VENDITA") -> 0 | I17: =SUMIFS(INDIRECT("'" & $I$4 & "'!$I$11:$I$1000"), INDIRECT("'" & $I$4 & "'!$G$11:$G$1000"), $E17, INDIRECT("'" & $I$4 & "'!$A$11:$A$1000"), "INZIA IL TRATTAMENTO-VENDITA") -> 0 | J17: =SUMIFS(INDIRECT("'" & J$4 & "'!$I$11:$I$1000"), INDIRECT("'" & J$4 & "'!$G$11:$G$1000"), $E17, INDIRECT("'" & J$4 & "'!$A$11:$A$1000"), "INZIA IL TRATTAMENTO-VENDITA") -> 0 | K17: =SUMIFS(INDIRECT("'" & K$4 & "'!$I$11:$I$1000"), INDIRECT("'" & K$4 & "'!$G$11:$G$1000"), $E17, INDIRECT("'" & K$4 & "'!$A$11:$A$1000"), "INZIA IL TRATTAMENTO-VENDITA") -> 0 | L17: =SUMIFS(INDIRECT("'" & L$4 & "'!$I$11:$I$1000"), INDIRECT("'" & L$4 & "'!$G$11:$G$1000"), $E17, INDIRECT("'" & L$4 & "'!$A$11:$A$1000"), "INZIA IL TRATTAMENTO-VENDITA") -> 0 | M17: =SUMIFS(INDIRECT("'" & M$4 & "'!$I$11:$I$1000"), INDIRECT("'" & M$4 & "'!$G$11:$G$1000"), $E17, INDIRECT("'" & M$4 & "'!$A$11:$A$1000"), "INZIA IL TRATTAMENTO-VENDITA") -> 0 | N17: =SUMIFS(INDIRECT("'" & N$4 & "'!$I$11:$I$1000"), INDIRECT("'" & N$4 & "'!$G$11:$G$1000"), $E17, INDIRECT("'" & N$4 & "'!$A$11:$A$1000"), "INZIA IL TRATTAMENTO-VENDITA") -> 0 | O17: =SUMIFS(INDIRECT("'" & O$4 & "'!$I$11:$I$1000"), INDIRECT("'" & O$4 & "'!$G$11:$G$1000"), $E17, INDIRECT("'" & O$4 & "'!$A$11:$A$1000"), "INZIA IL TRATTAMENTO-VENDITA") -> 0 | P17: =SUMIFS(INDIRECT("'" & P$4 & "'!$I$11:$I$1000"), INDIRECT("'" & P$4 & "'!$G$11:$G$1000"), $E17, INDIRECT("'" & P$4 & "'!$A$11:$A$1000"), "INZIA IL TRATTAMENTO-VENDITA") -> 0 | Q17: =SUMIFS(INDIRECT("'" & Q$4 & "'!$I$11:$I$1000"), INDIRECT("'" & Q$4 & "'!$G$11:$G$1000"), $E17, INDIRECT("'" & Q$4 & "'!$A$11:$A$1000"), "INZIA IL TRATTAMENTO-VENDITA") -> 0 | R17: =SUM(C17:Q17) -> 0
C18: =SUMIFS('OPPORTUNITA DI VENDITA'!$J$198:$J$1000, 'OPPORTUNITA DI VENDITA'!$H$198:$H$1000, B18, 'OPPORTUNITA DI VENDITA'!$B$198:$B$1000, "ESEGUITO") -> 0 | F18: =SUMIFS(INDIRECT("'" & $F$4 & "'!$I$11:$I$1000"), INDIRECT("'" & $F$4 & "'!$G$11:$G$1000"), $E18, INDIRECT("'" & $F$4 & "'!$A$11:$A$1000"), "INZIA IL TRATTAMENTO-VENDITA") -> 0 | G18: =SUMIFS(INDIRECT("'" & $G$4 & "'!$I$11:$I$1000"), INDIRECT("'" & $G$4 & "'!$G$11:$G$1000"), $E18, INDIRECT("'" & $G$4 & "'!$A$11:$A$1000"), "INZIA IL TRATTAMENTO-VENDITA") -> 0 | H18: =SUMIFS(INDIRECT("'" & $H$4 & "'!$I$11:$I$1000"), INDIRECT("'" & $H$4 & "'!$G$11:$G$1000"), $E18, INDIRECT("'" & $H$4 & "'!$A$11:$A$1000"), "INZIA IL TRATTAMENTO-VENDITA") -> 0 | I18: =SUMIFS(INDIRECT("'" & $I$4 & "'!$I$11:$I$1000"), INDIRECT("'" & $I$4 & "'!$G$11:$G$1000"), $E18, INDIRECT("'" & $I$4 & "'!$A$11:$A$1000"), "INZIA IL TRATTAMENTO-VENDITA") -> 0 | J18: =SUMIFS(INDIRECT("'" & J$4 & "'!$I$11:$I$1000"), INDIRECT("'" & J$4 & "'!$G$11:$G$1000"), $E18, INDIRECT("'" & J$4 & "'!$A$11:$A$1000"), "INZIA IL TRATTAMENTO-VENDITA") -> 0 | K18: =SUMIFS(INDIRECT("'" & K$4 & "'!$I$11:$I$1000"), INDIRECT("'" & K$4 & "'!$G$11:$G$1000"), $E18, INDIRECT("'" & K$4 & "'!$A$11:$A$1000"), "INZIA IL TRATTAMENTO-VENDITA") -> 0 | L18: =SUMIFS(INDIRECT("'" & L$4 & "'!$I$11:$I$1000"), INDIRECT("'" & L$4 & "'!$G$11:$G$1000"), $E18, INDIRECT("'" & L$4 & "'!$A$11:$A$1000"), "INZIA IL TRATTAMENTO-VENDITA") -> 0 | M18: =SUMIFS(INDIRECT("'" & M$4 & "'!$I$11:$I$1000"), INDIRECT("'" & M$4 & "'!$G$11:$G$1000"), $E18, INDIRECT("'" & M$4 & "'!$A$11:$A$1000"), "INZIA IL TRATTAMENTO-VENDITA") -> 0 | N18: =SUMIFS(INDIRECT("'" & N$4 & "'!$I$11:$I$1000"), INDIRECT("'" & N$4 & "'!$G$11:$G$1000"), $E18, INDIRECT("'" & N$4 & "'!$A$11:$A$1000"), "INZIA IL TRATTAMENTO-VENDITA") -> 0 | O18: =SUMIFS(INDIRECT("'" & O$4 & "'!$I$11:$I$1000"), INDIRECT("'" & O$4 & "'!$G$11:$G$1000"), $E18, INDIRECT("'" & O$4 & "'!$A$11:$A$1000"), "INZIA IL TRATTAMENTO-VENDITA") -> 0 | P18: =SUMIFS(INDIRECT("'" & P$4 & "'!$I$11:$I$1000"), INDIRECT("'" & P$4 & "'!$G$11:$G$1000"), $E18, INDIRECT("'" & P$4 & "'!$A$11:$A$1000"), "INZIA IL TRATTAMENTO-VENDITA") -> 0 | Q18: =SUMIFS(INDIRECT("'" & Q$4 & "'!$I$11:$I$1000"), INDIRECT("'" & Q$4 & "'!$G$11:$G$1000"), $E18, INDIRECT("'" & Q$4 & "'!$A$11:$A$1000"), "INZIA IL TRATTAMENTO-VENDITA") -> 0 | R18: =SUM(C18:Q18) -> 0
B19: Tot.Anno---> | C19: =SUM(C5:C18) -> 36232 | E19: Tot.Mese---> | F19: =SUM(F5:F18) -> 35484 | G19: =SUM(G5:G18) -> 104999 | H19: =SUM(H5:H18) -> 54103 | I19: =SUM(I5:I18) -> 23735 | J19: =SUM(J5:J18) -> 39216 | K19: =SUM(K5:K18) -> 24720 | L19: =SUM(L5:L18) -> 0 | M19: =SUM(M5:M18) -> 0 | ... R19: =SUM(R5:R18) -> 318489 | S19: <---Tot.Accettato Complessivo
B24: Consuntivo Annuale | C24: Opp.tà di Vendita | D24: Colonna 2 | E24: Preventivato Mese RIFIUTATO | F24: 1 | G24: 2 | H24: 3 | I24: 4 | J24: 5 | K24: 6 | L24: 7 | M24: 8 | N24: 9 | O24: 10 | P24: 11 | Q24: 12 | R24: TOTALE | S24: ,,
F25: gennaio | G25: febbraio | H25: marzo | I25: aprile | J25: maggio | K25: giugno | L25: luglio | M25: agosto | N25: settembre | O25: ottobre | P25: novembre | Q25: dicembre
B26: DOMENICI | C26: =SUMIFS('OPPORTUNITA DI VENDITA'!$J$198:$J$1000, 'OPPORTUNITA DI VENDITA'!$H$198:$H$1000, B26, 'OPPORTUNITA DI VENDITA'!$B$198:$B$1000, "NON ESEGUITO") -> 0 | E26: DOMENICI | F26: =SUMIFS(INDIRECT("'" & $F$4 & "'!$I$11:$I$1000"), INDIRECT("'" & $F$4 & "'!$G$11:$G$1000"), $E26, INDIRECT("'" & $F$4 & "'!$A$11:$A$1000"), "NESSUNA VENDITA") -> 26088 | G26: =SUMIFS(INDIRECT("'" & $G$4 & "'!$I$11:$I$1000"), INDIRECT("'" & $G$4 & "'!$G$11:$G$1000"), $E26, INDIRECT("'" & $G$4 & "'!$A$11:$A$1000"), "NESSUNA VENDITA") -> 75785 | H26: =SUMIFS(INDIRECT("'" & $H$4 & "'!$I$11:$I$1000"), INDIRECT("'" & $H$4 & "'!$G$11:$G$1000"), $E26, INDIRECT("'" & $H$4 & "'!$A$11:$A$1000"), "NESSUNA VENDITA") -> 2072 | I26: =SUMIFS(INDIRECT("'" & I$4 & "'!$I$11:$I$1000"), INDIRECT("'" & I$4 & "'!$G$11:$G$1000"), $E26, INDIRECT("'" & I$4 & "'!$A$11:$A$1000"), "NESSUNA VENDITA") -> 28522 | J26: =SUMIFS(INDIRECT("'" & J$4 & "'!$I$11:$I$1000"), INDIRECT("'" & J$4 & "'!$G$11:$G$1000"), $E26, INDIRECT("'" & J$4 & "'!$A$11:$A$1000"), "NESSUNA VENDITA") -> 22356 | K26: =SUMIFS(INDIRECT("'" & K$4 & "'!$I$11:$I$1000"), INDIRECT("'" & K$4 & "'!$G$11:$G$1000"), $E26, INDIRECT("'" & K$4 & "'!$A$11:$A$1000"), "NESSUNA VENDITA") -> 0 | L26: =SUMIFS(INDIRECT("'" & L$4 & "'!$I$11:$I$1000"), INDIRECT("'" & L$4 & "'!$G$11:$G$1000"), $E26, INDIRECT("'" & L$4 & "'!$A$11:$A$1000"), "NESSUNA VENDITA") -> 0 | M26: =SUMIFS(INDIRECT("'" & M$4 & "'!$I$11:$I$1000"), INDIRECT("'" & M$4 & "'!$G$11:$G$1000"), $E26, INDIRECT("'" & M$4 & "'!$A$11:$A$1000"), "NESSUNA VENDITA") -> 0 | N26: =SUMIFS(INDIRECT("'" & N$4 & "'!$I$11:$I$1000"), INDIRECT("'" & N$4 & "'!$G$11:$G$1000"), $E26, INDIRECT("'" & N$4 & "'!$A$11:$A$1000"), "NESSUNA VENDITA") -> 0 | O26: =SUMIFS(INDIRECT("'" & O$4 & "'!$I$11:$I$1000"), INDIRECT("'" & O$4 & "'!$G$11:$G$1000"), $E26, INDIRECT("'" & O$4 & "'!$A$11:$A$1000"), "NESSUNA VENDITA") -> 0 | P26: =SUMIFS(INDIRECT("'" & P$4 & "'!$I$11:$I$1000"), INDIRECT("'" & P$4 & "'!$G$11:$G$1000"), $E26, INDIRECT("'" & P$4 & "'!$A$11:$A$1000"), "NESSUNA VENDITA") -> 0 | Q26: =SUMIFS(INDIRECT("'" & Q$4 & "'!$I$11:$I$1000"), INDIRECT("'" & Q$4 & "'!$G$11:$G$1000"), $E26, INDIRECT("'" & Q$4 & "'!$A$11:$A$1000"), "NESSUNA VENDITA") -> 0 | R26: =SUM(C26:Q26) -> 154823
B27: AMOROSO | C27: =SUMIFS('OPPORTUNITA DI VENDITA'!$J$198:$J$1000, 'OPPORTUNITA DI VENDITA'!$H$198:$H$1000, B27, 'OPPORTUNITA DI VENDITA'!$B$198:$B$1000, "NON ESEGUITO") -> 0 | E27: AMOROSO | F27: =SUMIFS(INDIRECT("'" & $F$4 & "'!$I$11:$I$1000"), INDIRECT("'" & $F$4 & "'!$G$11:$G$1000"), $E27, INDIRECT("'" & $F$4 & "'!$A$11:$A$1000"), "NESSUNA VENDITA") -> 18880 | G27: =SUMIFS(INDIRECT("'" & $G$4 & "'!$I$11:$I$1000"), INDIRECT("'" & $G$4 & "'!$G$11:$G$1000"), $E27, INDIRECT("'" & $G$4 & "'!$A$11:$A$1000"), "NESSUNA VENDITA") -> 0 | H27: =SUMIFS(INDIRECT("'" & $H$4 & "'!$I$11:$I$1000"), INDIRECT("'" & $H$4 & "'!$G$11:$G$1000"), $E27, INDIRECT("'" & $H$4 & "'!$A$11:$A$1000"), "NESSUNA VENDITA") -> 32430 | I27: =SUMIFS(INDIRECT("'" & I$4 & "'!$I$11:$I$1000"), INDIRECT("'" & I$4 & "'!$G$11:$G$1000"), $E27, INDIRECT("'" & I$4 & "'!$A$11:$A$1000"), "NESSUNA VENDITA") -> 18555 | J27: =SUMIFS(INDIRECT("'" & J$4 & "'!$I$11:$I$1000"), INDIRECT("'" & J$4 & "'!$G$11:$G$1000"), $E27, INDIRECT("'" & J$4 & "'!$A$11:$A$1000"), "NESSUNA VENDITA") -> 15556 | K27: =SUMIFS(INDIRECT("'" & K$4 & "'!$I$11:$I$1000"), INDIRECT("'" & K$4 & "'!$G$11:$G$1000"), $E27, INDIRECT("'" & K$4 & "'!$A$11:$A$1000"), "NESSUNA VENDITA") -> 0 | L27: =SUMIFS(INDIRECT("'" & L$4 & "'!$I$11:$I$1000"), INDIRECT("'" & L$4 & "'!$G$11:$G$1000"), $E27, INDIRECT("'" & L$4 & "'!$A$11:$A$1000"), "NESSUNA VENDITA") -> 0 | M27: =SUMIFS(INDIRECT("'" & M$4 & "'!$I$11:$I$1000"), INDIRECT("'" & M$4 & "'!$G$11:$G$1000"), $E27, INDIRECT("'" & M$4 & "'!$A$11:$A$1000"), "NESSUNA VENDITA") -> 0 | N27: =SUMIFS(INDIRECT("'" & N$4 & "'!$I$11:$I$1000"), INDIRECT("'" & N$4 & "'!$G$11:$G$1000"), $E27, INDIRECT("'" & N$4 & "'!$A$11:$A$1000"), "NESSUNA VENDITA") -> 0 | O27: =SUMIFS(INDIRECT("'" & O$4 & "'!$I$11:$I$1000"), INDIRECT("'" & O$4 & "'!$G$11:$G$1000"), $E27, INDIRECT("'" & O$4 & "'!$A$11:$A$1000"), "NESSUNA VENDITA") -> 0 | P27: =SUMIFS(INDIRECT("'" & P$4 & "'!$I$11:$I$1000"), INDIRECT("'" & P$4 & "'!$G$11:$G$1000"), $E27, INDIRECT("'" & P$4 & "'!$A$11:$A$1000"), "NESSUNA VENDITA") -> 0 | Q27: =SUMIFS(INDIRECT("'" & Q$4 & "'!$I$11:$I$1000"), INDIRECT("'" & Q$4 & "'!$G$11:$G$1000"), $E27, INDIRECT("'" & Q$4 & "'!$A$11:$A$1000"), "NESSUNA VENDITA") -> 0 | R27: =SUM(C27:Q27) -> 85421
B28: INNOCENTE | C28: =SUMIFS('OPPORTUNITA DI VENDITA'!$J$198:$J$1000, 'OPPORTUNITA DI VENDITA'!$H$198:$H$1000, B28, 'OPPORTUNITA DI VENDITA'!$B$198:$B$1000, "NON ESEGUITO") -> 0 | E28: INNOCENTE | F28: =SUMIFS(INDIRECT("'" & $F$4 & "'!$I$11:$I$1000"), INDIRECT("'" & $F$4 & "'!$G$11:$G$1000"), $E28, INDIRECT("'" & $F$4 & "'!$A$11:$A$1000"), "NESSUNA VENDITA") -> 0 | G28: =SUMIFS(INDIRECT("'" & $G$4 & "'!$I$11:$I$1000"), INDIRECT("'" & $G$4 & "'!$G$11:$G$1000"), $E28, INDIRECT("'" & $G$4 & "'!$A$11:$A$1000"), "NESSUNA VENDITA") -> 0 | H28: =SUMIFS(INDIRECT("'" & $H$4 & "'!$I$11:$I$1000"), INDIRECT("'" & $H$4 & "'!$G$11:$G$1000"), $E28, INDIRECT("'" & $H$4 & "'!$A$11:$A$1000"), "NESSUNA VENDITA") -> 0 | I28: =SUMIFS(INDIRECT("'" & I$4 & "'!$I$11:$I$1000"), INDIRECT("'" & I$4 & "'!$G$11:$G$1000"), $E28, INDIRECT("'" & I$4 & "'!$A$11:$A$1000"), "NESSUNA VENDITA") -> 0 | J28: =SUMIFS(INDIRECT("'" & J$4 & "'!$I$11:$I$1000"), INDIRECT("'" & J$4 & "'!$G$11:$G$1000"), $E28, INDIRECT("'" & J$4 & "'!$A$11:$A$1000"), "NESSUNA VENDITA") -> 0 | K28: =SUMIFS(INDIRECT("'" & K$4 & "'!$I$11:$I$1000"), INDIRECT("'" & K$4 & "'!$G$11:$G$1000"), $E28, INDIRECT("'" & K$4 & "'!$A$11:$A$1000"), "NESSUNA VENDITA") -> 0 | L28: =SUMIFS(INDIRECT("'" & L$4 & "'!$I$11:$I$1000"), INDIRECT("'" & L$4 & "'!$G$11:$G$1000"), $E28, INDIRECT("'" & L$4 & "'!$A$11:$A$1000"), "NESSUNA VENDITA") -> 0 | M28: =SUMIFS(INDIRECT("'" & M$4 & "'!$I$11:$I$1000"), INDIRECT("'" & M$4 & "'!$G$11:$G$1000"), $E28, INDIRECT("'" & M$4 & "'!$A$11:$A$1000"), "NESSUNA VENDITA") -> 0 | N28: =SUMIFS(INDIRECT("'" & N$4 & "'!$I$11:$I$1000"), INDIRECT("'" & N$4 & "'!$G$11:$G$1000"), $E28, INDIRECT("'" & N$4 & "'!$A$11:$A$1000"), "NESSUNA VENDITA") -> 0 | O28: =SUMIFS(INDIRECT("'" & O$4 & "'!$I$11:$I$1000"), INDIRECT("'" & O$4 & "'!$G$11:$G$1000"), $E28, INDIRECT("'" & O$4 & "'!$A$11:$A$1000"), "NESSUNA VENDITA") -> 0 | P28: =SUMIFS(INDIRECT("'" & P$4 & "'!$I$11:$I$1000"), INDIRECT("'" & P$4 & "'!$G$11:$G$1000"), $E28, INDIRECT("'" & P$4 & "'!$A$11:$A$1000"), "NESSUNA VENDITA") -> 0 | Q28: =SUMIFS(INDIRECT("'" & Q$4 & "'!$I$11:$I$1000"), INDIRECT("'" & Q$4 & "'!$G$11:$G$1000"), $E28, INDIRECT("'" & Q$4 & "'!$A$11:$A$1000"), "NESSUNA VENDITA") -> 0 | R28: =SUM(C28:Q28) -> 0
B29: BERARDI | C29: =SUMIFS('OPPORTUNITA DI VENDITA'!$J$198:$J$1000, 'OPPORTUNITA DI VENDITA'!$H$198:$H$1000, B29, 'OPPORTUNITA DI VENDITA'!$B$198:$B$1000, "NON ESEGUITO") -> 0 | E29: BERARDI | F29: =SUMIFS(INDIRECT("'" & $F$4 & "'!$I$11:$I$1000"), INDIRECT("'" & $F$4 & "'!$G$11:$G$1000"), $E29, INDIRECT("'" & $F$4 & "'!$A$11:$A$1000"), "NESSUNA VENDITA") -> 0 | G29: =SUMIFS(INDIRECT("'" & $G$4 & "'!$I$11:$I$1000"), INDIRECT("'" & $G$4 & "'!$G$11:$G$1000"), $E29, INDIRECT("'" & $G$4 & "'!$A$11:$A$1000"), "NESSUNA VENDITA") -> 0 | H29: =SUMIFS(INDIRECT("'" & $H$4 & "'!$I$11:$I$1000"), INDIRECT("'" & $H$4 & "'!$G$11:$G$1000"), $E29, INDIRECT("'" & $H$4 & "'!$A$11:$A$1000"), "NESSUNA VENDITA") -> 0 | I29: =SUMIFS(INDIRECT("'" & I$4 & "'!$I$11:$I$1000"), INDIRECT("'" & I$4 & "'!$G$11:$G$1000"), $E29, INDIRECT("'" & I$4 & "'!$A$11:$A$1000"), "NESSUNA VENDITA") -> 0 | J29: =SUMIFS(INDIRECT("'" & J$4 & "'!$I$11:$I$1000"), INDIRECT("'" & J$4 & "'!$G$11:$G$1000"), $E29, INDIRECT("'" & J$4 & "'!$A$11:$A$1000"), "NESSUNA VENDITA") -> 0 | K29: =SUMIFS(INDIRECT("'" & K$4 & "'!$I$11:$I$1000"), INDIRECT("'" & K$4 & "'!$G$11:$G$1000"), $E29, INDIRECT("'" & K$4 & "'!$A$11:$A$1000"), "NESSUNA VENDITA") -> 0 | L29: =SUMIFS(INDIRECT("'" & L$4 & "'!$I$11:$I$1000"), INDIRECT("'" & L$4 & "'!$G$11:$G$1000"), $E29, INDIRECT("'" & L$4 & "'!$A$11:$A$1000"), "NESSUNA VENDITA") -> 0 | M29: =SUMIFS(INDIRECT("'" & M$4 & "'!$I$11:$I$1000"), INDIRECT("'" & M$4 & "'!$G$11:$G$1000"), $E29, INDIRECT("'" & M$4 & "'!$A$11:$A$1000"), "NESSUNA VENDITA") -> 0 | N29: =SUMIFS(INDIRECT("'" & N$4 & "'!$I$11:$I$1000"), INDIRECT("'" & N$4 & "'!$G$11:$G$1000"), $E29, INDIRECT("'" & N$4 & "'!$A$11:$A$1000"), "NESSUNA VENDITA") -> 0 | O29: =SUMIFS(INDIRECT("'" & O$4 & "'!$I$11:$I$1000"), INDIRECT("'" & O$4 & "'!$G$11:$G$1000"), $E29, INDIRECT("'" & O$4 & "'!$A$11:$A$1000"), "NESSUNA VENDITA") -> 0 | P29: =SUMIFS(INDIRECT("'" & P$4 & "'!$I$11:$I$1000"), INDIRECT("'" & P$4 & "'!$G$11:$G$1000"), $E29, INDIRECT("'" & P$4 & "'!$A$11:$A$1000"), "NESSUNA VENDITA") -> 0 | Q29: =SUMIFS(INDIRECT("'" & Q$4 & "'!$I$11:$I$1000"), INDIRECT("'" & Q$4 & "'!$G$11:$G$1000"), $E29, INDIRECT("'" & Q$4 & "'!$A$11:$A$1000"), "NESSUNA VENDITA") -> 0 | R29: =SUM(C29:Q29) -> 0
B30: BERNARDINI | C30: =SUMIFS('OPPORTUNITA DI VENDITA'!$J$198:$J$1000, 'OPPORTUNITA DI VENDITA'!$H$198:$H$1000, B30, 'OPPORTUNITA DI VENDITA'!$B$198:$B$1000, "NON ESEGUITO") -> 0 | E30: BERNARDINI | F30: =SUMIFS(INDIRECT("'" & $F$4 & "'!$I$11:$I$1000"), INDIRECT("'" & $F$4 & "'!$G$11:$G$1000"), $E30, INDIRECT("'" & $F$4 & "'!$A$11:$A$1000"), "NESSUNA VENDITA") -> 0 | G30: =SUMIFS(INDIRECT("'" & $G$4 & "'!$I$11:$I$1000"), INDIRECT("'" & $G$4 & "'!$G$11:$G$1000"), $E30, INDIRECT("'" & $G$4 & "'!$A$11:$A$1000"), "NESSUNA VENDITA") -> 0 | H30: =SUMIFS(INDIRECT("'" & $H$4 & "'!$I$11:$I$1000"), INDIRECT("'" & $H$4 & "'!$G$11:$G$1000"), $E30, INDIRECT("'" & $H$4 & "'!$A$11:$A$1000"), "NESSUNA VENDITA") -> 0 | I30: =SUMIFS(INDIRECT("'" & I$4 & "'!$I$11:$I$1000"), INDIRECT("'" & I$4 & "'!$G$11:$G$1000"), $E30, INDIRECT("'" & I$4 & "'!$A$11:$A$1000"), "NESSUNA VENDITA") -> 0 | J30: =SUMIFS(INDIRECT("'" & J$4 & "'!$I$11:$I$1000"), INDIRECT("'" & J$4 & "'!$G$11:$G$1000"), $E30, INDIRECT("'" & J$4 & "'!$A$11:$A$1000"), "NESSUNA VENDITA") -> 0 | K30: =SUMIFS(INDIRECT("'" & K$4 & "'!$I$11:$I$1000"), INDIRECT("'" & K$4 & "'!$G$11:$G$1000"), $E30, INDIRECT("'" & K$4 & "'!$A$11:$A$1000"), "NESSUNA VENDITA") -> 0 | L30: =SUMIFS(INDIRECT("'" & L$4 & "'!$I$11:$I$1000"), INDIRECT("'" & L$4 & "'!$G$11:$G$1000"), $E30, INDIRECT("'" & L$4 & "'!$A$11:$A$1000"), "NESSUNA VENDITA") -> 0 | M30: =SUMIFS(INDIRECT("'" & M$4 & "'!$I$11:$I$1000"), INDIRECT("'" & M$4 & "'!$G$11:$G$1000"), $E30, INDIRECT("'" & M$4 & "'!$A$11:$A$1000"), "NESSUNA VENDITA") -> 0 | N30: =SUMIFS(INDIRECT("'" & N$4 & "'!$I$11:$I$1000"), INDIRECT("'" & N$4 & "'!$G$11:$G$1000"), $E30, INDIRECT("'" & N$4 & "'!$A$11:$A$1000"), "NESSUNA VENDITA") -> 0 | O30: =SUMIFS(INDIRECT("'" & O$4 & "'!$I$11:$I$1000"), INDIRECT("'" & O$4 & "'!$G$11:$G$1000"), $E30, INDIRECT("'" & O$4 & "'!$A$11:$A$1000"), "NESSUNA VENDITA") -> 0 | P30: =SUMIFS(INDIRECT("'" & P$4 & "'!$I$11:$I$1000"), INDIRECT("'" & P$4 & "'!$G$11:$G$1000"), $E30, INDIRECT("'" & P$4 & "'!$A$11:$A$1000"), "NESSUNA VENDITA") -> 0 | Q30: =SUMIFS(INDIRECT("'" & Q$4 & "'!$I$11:$I$1000"), INDIRECT("'" & Q$4 & "'!$G$11:$G$1000"), $E30, INDIRECT("'" & Q$4 & "'!$A$11:$A$1000"), "NESSUNA VENDITA") -> 0 | R30: =SUM(C30:Q30) -> 0
B31: MASTRORILLI | C31: =SUMIFS('OPPORTUNITA DI VENDITA'!$J$198:$J$1000, 'OPPORTUNITA DI VENDITA'!$H$198:$H$1000, B31, 'OPPORTUNITA DI VENDITA'!$B$198:$B$1000, "NON ESEGUITO") -> 0 | E31: MASTRORILLI | F31: =SUMIFS(INDIRECT("'" & $F$4 & "'!$I$11:$I$1000"), INDIRECT("'" & $F$4 & "'!$G$11:$G$1000"), $E31, INDIRECT("'" & $F$4 & "'!$A$11:$A$1000"), "NESSUNA VENDITA") -> 0 | G31: =SUMIFS(INDIRECT("'" & $G$4 & "'!$I$11:$I$1000"), INDIRECT("'" & $G$4 & "'!$G$11:$G$1000"), $E31, INDIRECT("'" & $G$4 & "'!$A$11:$A$1000"), "NESSUNA VENDITA") -> 0 | H31: =SUMIFS(INDIRECT("'" & $H$4 & "'!$I$11:$I$1000"), INDIRECT("'" & $H$4 & "'!$G$11:$G$1000"), $E31, INDIRECT("'" & $H$4 & "'!$A$11:$A$1000"), "NESSUNA VENDITA") -> 0 | I31: =SUMIFS(INDIRECT("'" & I$4 & "'!$I$11:$I$1000"), INDIRECT("'" & I$4 & "'!$G$11:$G$1000"), $E31, INDIRECT("'" & I$4 & "'!$A$11:$A$1000"), "NESSUNA VENDITA") -> 6500 | J31: =SUMIFS(INDIRECT("'" & J$4 & "'!$I$11:$I$1000"), INDIRECT("'" & J$4 & "'!$G$11:$G$1000"), $E31, INDIRECT("'" & J$4 & "'!$A$11:$A$1000"), "NESSUNA VENDITA") -> 0 | K31: =SUMIFS(INDIRECT("'" & K$4 & "'!$I$11:$I$1000"), INDIRECT("'" & K$4 & "'!$G$11:$G$1000"), $E31, INDIRECT("'" & K$4 & "'!$A$11:$A$1000"), "NESSUNA VENDITA") -> 0 | L31: =SUMIFS(INDIRECT("'" & L$4 & "'!$I$11:$I$1000"), INDIRECT("'" & L$4 & "'!$G$11:$G$1000"), $E31, INDIRECT("'" & L$4 & "'!$A$11:$A$1000"), "NESSUNA VENDITA") -> 0 | M31: =SUMIFS(INDIRECT("'" & M$4 & "'!$I$11:$I$1000"), INDIRECT("'" & M$4 & "'!$G$11:$G$1000"), $E31, INDIRECT("'" & M$4 & "'!$A$11:$A$1000"), "NESSUNA VENDITA") -> 0 | N31: =SUMIFS(INDIRECT("'" & N$4 & "'!$I$11:$I$1000"), INDIRECT("'" & N$4 & "'!$G$11:$G$1000"), $E31, INDIRECT("'" & N$4 & "'!$A$11:$A$1000"), "NESSUNA VENDITA") -> 0 | O31: =SUMIFS(INDIRECT("'" & O$4 & "'!$I$11:$I$1000"), INDIRECT("'" & O$4 & "'!$G$11:$G$1000"), $E31, INDIRECT("'" & O$4 & "'!$A$11:$A$1000"), "NESSUNA VENDITA") -> 0 | P31: =SUMIFS(INDIRECT("'" & P$4 & "'!$I$11:$I$1000"), INDIRECT("'" & P$4 & "'!$G$11:$G$1000"), $E31, INDIRECT("'" & P$4 & "'!$A$11:$A$1000"), "NESSUNA VENDITA") -> 0 | Q31: =SUMIFS(INDIRECT("'" & Q$4 & "'!$I$11:$I$1000"), INDIRECT("'" & Q$4 & "'!$G$11:$G$1000"), $E31, INDIRECT("'" & Q$4 & "'!$A$11:$A$1000"), "NESSUNA VENDITA") -> 0 | R31: =SUM(C31:Q31) -> 6500
B32: CARDONE | C32: =SUMIFS('OPPORTUNITA DI VENDITA'!$J$198:$J$1000, 'OPPORTUNITA DI VENDITA'!$H$198:$H$1000, B32, 'OPPORTUNITA DI VENDITA'!$B$198:$B$1000, "NON ESEGUITO") -> 0 | E32: CARDONE | F32: =SUMIFS(INDIRECT("'" & $F$4 & "'!$I$11:$I$1000"), INDIRECT("'" & $F$4 & "'!$G$11:$G$1000"), $E32, INDIRECT("'" & $F$4 & "'!$A$11:$A$1000"), "NESSUNA VENDITA") -> 5800 | G32: =SUMIFS(INDIRECT("'" & $G$4 & "'!$I$11:$I$1000"), INDIRECT("'" & $G$4 & "'!$G$11:$G$1000"), $E32, INDIRECT("'" & $G$4 & "'!$A$11:$A$1000"), "NESSUNA VENDITA") -> 0 | H32: =SUMIFS(INDIRECT("'" & $H$4 & "'!$I$11:$I$1000"), INDIRECT("'" & $H$4 & "'!$G$11:$G$1000"), $E32, INDIRECT("'" & $H$4 & "'!$A$11:$A$1000"), "NESSUNA VENDITA") -> 6790 | I32: =SUMIFS(INDIRECT("'" & I$4 & "'!$I$11:$I$1000"), INDIRECT("'" & I$4 & "'!$G$11:$G$1000"), $E32, INDIRECT("'" & I$4 & "'!$A$11:$A$1000"), "NESSUNA VENDITA") -> 9400 | J32: =SUMIFS(INDIRECT("'" & J$4 & "'!$I$11:$I$1000"), INDIRECT("'" & J$4 & "'!$G$11:$G$1000"), $E32, INDIRECT("'" & J$4 & "'!$A$11:$A$1000"), "NESSUNA VENDITA") -> 0 | K32: =SUMIFS(INDIRECT("'" & K$4 & "'!$I$11:$I$1000"), INDIRECT("'" & K$4 & "'!$G$11:$G$1000"), $E32, INDIRECT("'" & K$4 & "'!$A$11:$A$1000"), "NESSUNA VENDITA") -> 0 | L32: =SUMIFS(INDIRECT("'" & L$4 & "'!$I$11:$I$1000"), INDIRECT("'" & L$4 & "'!$G$11:$G$1000"), $E32, INDIRECT("'" & L$4 & "'!$A$11:$A$1000"), "NESSUNA VENDITA") -> 0 | M32: =SUMIFS(INDIRECT("'" & M$4 & "'!$I$11:$I$1000"), INDIRECT("'" & M$4 & "'!$G$11:$G$1000"), $E32, INDIRECT("'" & M$4 & "'!$A$11:$A$1000"), "NESSUNA VENDITA") -> 0 | N32: =SUMIFS(INDIRECT("'" & N$4 & "'!$I$11:$I$1000"), INDIRECT("'" & N$4 & "'!$G$11:$G$1000"), $E32, INDIRECT("'" & N$4 & "'!$A$11:$A$1000"), "NESSUNA VENDITA") -> 0 | O32: =SUMIFS(INDIRECT("'" & O$4 & "'!$I$11:$I$1000"), INDIRECT("'" & O$4 & "'!$G$11:$G$1000"), $E32, INDIRECT("'" & O$4 & "'!$A$11:$A$1000"), "NESSUNA VENDITA") -> 0 | P32: =SUMIFS(INDIRECT("'" & P$4 & "'!$I$11:$I$1000"), INDIRECT("'" & P$4 & "'!$G$11:$G$1000"), $E32, INDIRECT("'" & P$4 & "'!$A$11:$A$1000"), "NESSUNA VENDITA") -> 0 | Q32: =SUMIFS(INDIRECT("'" & Q$4 & "'!$I$11:$I$1000"), INDIRECT("'" & Q$4 & "'!$G$11:$G$1000"), $E32, INDIRECT("'" & Q$4 & "'!$A$11:$A$1000"), "NESSUNA VENDITA") -> 0 | R32: =SUM(C32:Q32) -> 21990
B33: MARCANTONI | C33: =SUMIFS('OPPORTUNITA DI VENDITA'!$J$198:$J$1000, 'OPPORTUNITA DI VENDITA'!$H$198:$H$1000, B33, 'OPPORTUNITA DI VENDITA'!$B$198:$B$1000, "NON ESEGUITO") -> 0 | E33: MARCANTONI | F33: =SUMIFS(INDIRECT("'" & $F$4 & "'!$I$11:$I$1000"), INDIRECT("'" & $F$4 & "'!$G$11:$G$1000"), $E33, INDIRECT("'" & $F$4 & "'!$A$11:$A$1000"), "NESSUNA VENDITA") -> 0 | G33: =SUMIFS(INDIRECT("'" & $G$4 & "'!$I$11:$I$1000"), INDIRECT("'" & $G$4 & "'!$G$11:$G$1000"), $E33, INDIRECT("'" & $G$4 & "'!$A$11:$A$1000"), "NESSUNA VENDITA") -> 0 | H33: =SUMIFS(INDIRECT("'" & $H$4 & "'!$I$11:$I$1000"), INDIRECT("'" & $H$4 & "'!$G$11:$G$1000"), $E33, INDIRECT("'" & $H$4 & "'!$A$11:$A$1000"), "NESSUNA VENDITA") -> 1212 | I33: =SUMIFS(INDIRECT("'" & I$4 & "'!$I$11:$I$1000"), INDIRECT("'" & I$4 & "'!$G$11:$G$1000"), $E33, INDIRECT("'" & I$4 & "'!$A$11:$A$1000"), "NESSUNA VENDITA") -> 0 | J33: =SUMIFS(INDIRECT("'" & J$4 & "'!$I$11:$I$1000"), INDIRECT("'" & J$4 & "'!$G$11:$G$1000"), $E33, INDIRECT("'" & J$4 & "'!$A$11:$A$1000"), "NESSUNA VENDITA") -> 0 | K33: =SUMIFS(INDIRECT("'" & K$4 & "'!$I$11:$I$1000"), INDIRECT("'" & K$4 & "'!$G$11:$G$1000"), $E33, INDIRECT("'" & K$4 & "'!$A$11:$A$1000"), "NESSUNA VENDITA") -> 0 | L33: =SUMIFS(INDIRECT("'" & L$4 & "'!$I$11:$I$1000"), INDIRECT("'" & L$4 & "'!$G$11:$G$1000"), $E33, INDIRECT("'" & L$4 & "'!$A$11:$A$1000"), "NESSUNA VENDITA") -> 0 | M33: =SUMIFS(INDIRECT("'" & M$4 & "'!$I$11:$I$1000"), INDIRECT("'" & M$4 & "'!$G$11:$G$1000"), $E33, INDIRECT("'" & M$4 & "'!$A$11:$A$1000"), "NESSUNA VENDITA") -> 0 | N33: =SUMIFS(INDIRECT("'" & N$4 & "'!$I$11:$I$1000"), INDIRECT("'" & N$4 & "'!$G$11:$G$1000"), $E33, INDIRECT("'" & N$4 & "'!$A$11:$A$1000"), "NESSUNA VENDITA") -> 0 | O33: =SUMIFS(INDIRECT("'" & O$4 & "'!$I$11:$I$1000"), INDIRECT("'" & O$4 & "'!$G$11:$G$1000"), $E33, INDIRECT("'" & O$4 & "'!$A$11:$A$1000"), "NESSUNA VENDITA") -> 0 | P33: =SUMIFS(INDIRECT("'" & P$4 & "'!$I$11:$I$1000"), INDIRECT("'" & P$4 & "'!$G$11:$G$1000"), $E33, INDIRECT("'" & P$4 & "'!$A$11:$A$1000"), "NESSUNA VENDITA") -> 0 | Q33: =SUMIFS(INDIRECT("'" & Q$4 & "'!$I$11:$I$1000"), INDIRECT("'" & Q$4 & "'!$G$11:$G$1000"), $E33, INDIRECT("'" & Q$4 & "'!$A$11:$A$1000"), "NESSUNA VENDITA") -> 0 | R33: =SUM(C33:Q33) -> 1212
B34: MIRACOLO | C34: =SUMIFS('OPPORTUNITA DI VENDITA'!$J$198:$J$1000, 'OPPORTUNITA DI VENDITA'!$H$198:$H$1000, B34, 'OPPORTUNITA DI VENDITA'!$B$198:$B$1000, "NON ESEGUITO") -> 0 | E34: MIRACOLO | F34: =SUMIFS(INDIRECT("'" & $F$4 & "'!$I$11:$I$1000"), INDIRECT("'" & $F$4 & "'!$G$11:$G$1000"), $E34, INDIRECT("'" & $F$4 & "'!$A$11:$A$1000"), "NESSUNA VENDITA") -> 5380 | G34: =SUMIFS(INDIRECT("'" & $G$4 & "'!$I$11:$I$1000"), INDIRECT("'" & $G$4 & "'!$G$11:$G$1000"), $E34, INDIRECT("'" & $G$4 & "'!$A$11:$A$1000"), "NESSUNA VENDITA") -> 0 | H34: =SUMIFS(INDIRECT("'" & $H$4 & "'!$I$11:$I$1000"), INDIRECT("'" & $H$4 & "'!$G$11:$G$1000"), $E34, INDIRECT("'" & $H$4 & "'!$A$11:$A$1000"), "NESSUNA VENDITA") -> 5781 | I34: =SUMIFS(INDIRECT("'" & I$4 & "'!$I$11:$I$1000"), INDIRECT("'" & I$4 & "'!$G$11:$G$1000"), $E34, INDIRECT("'" & I$4 & "'!$A$11:$A$1000"), "NESSUNA VENDITA") -> 7900 | J34: =SUMIFS(INDIRECT("'" & J$4 & "'!$I$11:$I$1000"), INDIRECT("'" & J$4 & "'!$G$11:$G$1000"), $E34, INDIRECT("'" & J$4 & "'!$A$11:$A$1000"), "NESSUNA VENDITA") -> 0 | K34: =SUMIFS(INDIRECT("'" & K$4 & "'!$I$11:$I$1000"), INDIRECT("'" & K$4 & "'!$G$11:$G$1000"), $E34, INDIRECT("'" & K$4 & "'!$A$11:$A$1000"), "NESSUNA VENDITA") -> 0 | L34: =SUMIFS(INDIRECT("'" & L$4 & "'!$I$11:$I$1000"), INDIRECT("'" & L$4 & "'!$G$11:$G$1000"), $E34, INDIRECT("'" & L$4 & "'!$A$11:$A$1000"), "NESSUNA VENDITA") -> 0 | M34: =SUMIFS(INDIRECT("'" & M$4 & "'!$I$11:$I$1000"), INDIRECT("'" & M$4 & "'!$G$11:$G$1000"), $E34, INDIRECT("'" & M$4 & "'!$A$11:$A$1000"), "NESSUNA VENDITA") -> 0 | N34: =SUMIFS(INDIRECT("'" & N$4 & "'!$I$11:$I$1000"), INDIRECT("'" & N$4 & "'!$G$11:$G$1000"), $E34, INDIRECT("'" & N$4 & "'!$A$11:$A$1000"), "NESSUNA VENDITA") -> 0 | O34: =SUMIFS(INDIRECT("'" & O$4 & "'!$I$11:$I$1000"), INDIRECT("'" & O$4 & "'!$G$11:$G$1000"), $E34, INDIRECT("'" & O$4 & "'!$A$11:$A$1000"), "NESSUNA VENDITA") -> 0 | P34: =SUMIFS(INDIRECT("'" & P$4 & "'!$I$11:$I$1000"), INDIRECT("'" & P$4 & "'!$G$11:$G$1000"), $E34, INDIRECT("'" & P$4 & "'!$A$11:$A$1000"), "NESSUNA VENDITA") -> 0 | Q34: =SUMIFS(INDIRECT("'" & Q$4 & "'!$I$11:$I$1000"), INDIRECT("'" & Q$4 & "'!$G$11:$G$1000"), $E34, INDIRECT("'" & Q$4 & "'!$A$11:$A$1000"), "NESSUNA VENDITA") -> 0 | R34: =SUM(C34:Q34) -> 19061
